Workbook
Name 돋움: #REF!
Name 돋움: #REF!
Name 돋움: #REF!
Name 돋움: #REF!
Name 돋움: #REF!
Name 돋움: #REF!
Name 돋움: #REF!
Name 돋움: #REF!
Name 돋움: #REF!

Sheet WLAN 2.4 GHz Legacy
B2: SISO (Antenna 1)
B3: 2.4 GHz Legacy
B4: Mode | C4: Freq. | D4: Channel | E4: Data Rate | F4: PLS | G4: Average Power(㏈m) | H4: Tune-Up Power(㏈m) | I4: Peak Gain(dBi) | J4: E.I.R.P
B5: 802.11b | C5: 2412 | D5: 1 | E5: 1 | F5: 18 | G5: 19.16 | H5: 20 | I5: -6.46 | J5: =G22+I5 -> 12.75
C6: 2442 | D6: 7 | E6: 1 | F6: 18 | G6: 19.41 | H6: 20 | I6: -6.46 | J6: =G23+I6 -> 12.37
C7: 2472 | D7: 13 | E7: 1 | F7: 18 | G7: 18.68 | H7: 20 | I7: -6.46 | J7: =G24+I7 -> 13.01
B8: 802.11g | C8: 2412 | D8: 1 | E8: 6 | F8: 16 | G8: 16.27 | H8: 20 | I8: -6.46 | J8: =G8+I8 -> 9.81
C9: 2442 | D9: 7 | E9: 6 | F9: 16 | G9: 15.74 | H9: 20 | I9: -6.46 | J9: =G9+I9 -> 9.28
C10: 2472 | D10: 13 | E10: 6 | F10: 16 | G10: 16.14 | H10: 20 | I10: -6.46 | J10: =G10+I10 -> 9.68
B11: 802.11n HT20 | C11: 2412 | D11: 1 | E11: MCS0 | F11: 16 | G11: 16.36 | H11: 20 | I11: -6.46 | J11: =G11+I11 -> 9.9
C12: 2442 | D12: 7 | E12: MCS0 | F12: 16 | G12: 15.83 | H12: 20 | I12: -6.46 | J12: =G12+I12 -> 9.37
C13: 2472 | D13: 13 | E13: MCS0 | F13: 16 | G13: 16.44 | H13: 20 | I13: -6.46 | J13: =G13+I13 -> 9.98
B14: 802.11n HT40 | C14: 2422 | D14: 3 | E14: MCS0 | F14: 16 | G14: 19.34 | H14: 20 | I14: -6.46 | J14: =G14+I14 -> 12.88
C15: 2442 | D15: 7 | E15: MCS0 | F15: 16 | G15: 19.21 | H15: 20 | I15: -6.46 | J15: =G15+I15 -> 12.75
C16: 2462 | D16: 11 | E16: MCS0 | F16: 16 | G16: 18.99 | H16: 20 | I16: -6.46 | J16: =G16+I16 -> 12.53
B19: SISO (Antenna 2)
B20: 2.4 GHz Legacy
B21: Mode | C21: Freq. | D21: Channel | E21: Data Rate | F21: PLS | G21: Average Power(㏈m) | H21: Tune-Up Power(㏈m) | I21: Peak Gain(dBi) | J21: E.I.R.P
B22: 802.11b | C22: 2412 | D22: 1 | E22: 1 | F22: 18 | G22: 19.21 | H22: 20 | I22: -6 | J22: =G22+I22 -> 13.21
C23: 2442 | D23: 7 | E23: 1 | F23: 18 | G23: 18.83 | H23: 20 | I23: -6 | J23: =G23+I23 -> 12.83
C24: 2472 | D24: 13 | E24: 1 | F24: 18 | G24: 19.47 | H24: 20 | I24: -6 | J24: =G24+I24 -> 13.47
B25: 802.11g | C25: 2412 | D25: 1 | E25: 6 | F25: 16 | G25: 16.04 | H25: 20 | I25: -6 | J25: =G25+I25 -> 10.04
C26: 2442 | D26: 7 | E26: 6 | F26: 16 | G26: 15.48 | H26: 20 | I26: -6 | J26: =G26+I26 -> 9.48
C27: 2472 | D27: 13 | E27: 6 | F27: 16 | G27: 15.81 | H27: 20 | I27: -6 | J27: =G27+I27 -> 9.81
B28: 802.11n HT20 | C28: 2412 | D28: 1 | E28: MCS0 | F28: 16 | G28: 15.86 | H28: 20 | I28: -6 | J28: =G28+I28 -> 9.86
C29: 2442 | D29: 7 | E29: MCS0 | F29: 16 | G29: 15.18 | H29: 20 | I29: -6 | J29: =G29+I29 -> 9.18
C30: 2472 | D30: 13 | E30: MCS0 | F30: 16 | G30: 15.52 | H30: 20 | I30: -6 | J30: =G30+I30 -> 9.52
B31: 802.11n HT40 | C31: 2422 | D31: 3 | E31: MCS0 | F31: 16 | G31: 15.48 | H31: 20 | I31: -6 | J31: =G31+I31 -> 9.48
C32: 2442 | D32: 7 | E32: MCS0 | F32: 16 | G32: 15.81 | H32: 20 | I32: -6 | J32: =G32+I32 -> 9.81
C33: 2462 | D33: 11 | E33: MCS0 | F33: 16 | G33: 15.86 | H33: 20 | I33: -6 | J33: =G33+I33 -> 9.86
B36: MIMO (Antenna 1 + Antenna 2)
B37: 2.4 GHz Legacy
B38: Mode | C38: Freq. | D38: Channel | E38: Data Rate | F38: Ant.1 PLS | G38: Ant.2 PLS | H38: Ant.1 Average Power(㏈m) | I38: Ant.2 Average Power(㏈m) | J38: Tune-Up Power(㏈m) | K38: Ant.1+Ant.2 Average Power(㏈m) | L38: Tune-Up Power(㏈m) | M38: Peak Gain(dBi) | N38: E.I.R.P
B39: 802.11b | C39: 2412 | D39: 1 | E39: 1 | F39: 18 | G39: 18 | H39: 19.16 | I39: 19.21 | J39: 19 | K39: =10*LOG10((10^(H39/10))+(10^(I39/10))) -> 22.195372 | L39: 23 | M39: -6.46 | N39: =K39+M39 -> 15.735372
C40: 2442 | D40: 7 | E40: 1 | F40: 18 | G40: 18 | H40: 19.41 | I40: 18.83 | J40: 19 | K40: =10*LOG10((10^(H40/10))+(10^(I40/10))) -> 22.139975 | L40: 23 | M40: -6.46 | N40: =K40+M40 -> 15.679975
C41: 2472 | D41: 13 | E41: 1 | F41: 18 | G41: 18 | H41: 18.68 | I41: 19.47 | J41: 19 | K41: =10*LOG10((10^(H41/10))+(10^(I41/10))) -> 22.103238 | L41: 23 | M41: -6.46 | N41: =K41+M41 -> 15.643238
B42: 802.11g | C42: 2412 | D42: 1 | E42: 9 | F42: 16 | G42: 16 | H42: 16.27 | I42: 16.04 | J42: 19 | K42: =10*LOG10((10^(H42/10))+(10^(I42/10))) -> 19.166822 | L42: 23 | M42: -6.46 | N42: =K42+M42 -> 12.706822
C43: 2442 | D43: 7 | E43: 9 | F43: 16 | G43: 16 | H43: 15.74 | I43: 15.48 | J43: 19 | K43: =10*LOG10((10^(H43/10))+(10^(I43/10))) -> 18.622245 | L43: 23 | M43: -6.46 | N43: =K43+M43 -> 12.162245
C44: 2472 | D44: 13 | E44: 9 | F44: 16 | G44: 16 | H44: 16.14 | I44: 15.81 | J44: 19 | K44: =10*LOG10((10^(H44/10))+(10^(I44/10))) -> 18.988434 | L44: 23 | M44: -6.46 | N44: =K44+M44 -> 12.528434
B45: 802.11n HT20 | C45: 2412 | D45: 1 | E45: MCS8 | F45: 16 | G45: 16 | H45: 16.36 | I45: 15.86 | J45: 19 | K45: =10*LOG10((10^(H45/10))+(10^(I45/10))) -> 19.127492 | L45: 23 | M45: -6.46 | N45: =K45+M45 -> 12.667492
...

Sheet WLAN 5 GHz Legacy
BF1: =COUNTBLANK(AL54:AL64) -> 0 | BG1: =COUNTBLANK(AM54:AM64) -> 0
B2: SISO (Antenna 1)
B3: 5.2 &5.3 GHz Legacy | Q3: 5.5 & 5.6 GHz Legacy | AF3: 5.8 GHz Legacy
B4: Mode | C4: Freq. | D4: Channel | E4: Data Rate | F4: PLS | G4: Average Power(㏈m) | H4: Tune-Up Power(㏈m) | I4: Peak Gain(dBi) | J4: E.I.R.P | Q4: Mode | R4: Freq. | S4: Channel | T4: Data Rate | U4: PLS | V4: Average Power(㏈m) | W4: Tune-Up Power(㏈m) | X4: Peak Gain(dBi) | Y4: E.I.R.P | AF4: Mode | AG4: Freq. | AH4: Channel | AI4: Data Rate | AJ4: PLS | AK4: Average Power(㏈m) | AL4: Tune-Up Power(㏈m) | AM4: Peak Gain(dBi) | AN4: E.I.R.P
B5: 802.11a | C5: 5180 | D5: 36 | E5: 6 | F5: 16 | G5: 16.07 | H5: 17 | I5: -0.8 | J5: =I5+G5 -> 15.27 | Q5: 802.11a | R5: 5500 | S5: 100 | T5: 6 | U5: 16 | V5: 15.27 | W5: 17 | X5: -4.2 | Y5: =X5+V5 -> 11.07 | AF5: 802.11a | AG5: 5745 | AH5: 149 | AI5: 6 | AJ5: 16 | AK5: 9.31 | AL5: 17 | AM5: -3.2 | AN5: =AM5+AK5 -> 6.11
C6: 5260 | D6: 52 | E6: 6 | F6: 16 | G6: 16.07 | H6: 17 | I6: -0.8 | J6: =I6+G6 -> 15.27 | R6: 5600 | S6: 120 | T6: 6 | U6: 16 | V6: 15.27 | W6: 17 | X6: -4.2 | Y6: =X6+V6 -> 11.07 | AG6: 5785 | AH6: 157 | AI6: 6 | AJ6: 16 | AK6: 9.2 | AL6: 17 | AM6: -3.2 | AN6: =AM6+AK6 -> 6
C7: 5320 | D7: 64 | E7: 6 | F7: 16 | G7: 16.19 | H7: 17 | I7: -0.8 | J7: =I7+G7 -> 15.39 | R7: 5700 | S7: 140 | T7: 6 | U7: 16 | V7: 15.13 | W7: 17 | X7: -4.2 | Y7: =X7+V7 -> 10.93 | AG7: 5825 | AH7: 165 | AI7: 6 | AJ7: 16 | AK7: 9.63 | AL7: 17 | AM7: -3.2 | AN7: =AM7+AK7 -> 6.43
B8: 802.11n HT20 | C8: 5180 | D8: 36 | E8: MCS0 | F8: 16 | G8: 15.54 | H8: 17 | I8: -0.8 | J8: =I8+G8 -> 14.74 | Q8: 802.11n HT20 | R8: 5500 | S8: 100 | T8: MCS0 | U8: 16 | V8: 15.43 | W8: 17 | X8: -4.2 | Y8: =X8+V8 -> 11.23 | AF8: 802.11n HT20 | AG8: 5745 | AH8: 149 | AI8: MCS0 | AJ8: 16 | AK8: 9.52 | AL8: 17 | AM8: -3.2 | AN8: =AM8+AK8 -> 6.32
C9: 5260 | D9: 52 | E9: MCS0 | F9: 16 | G9: 16.32 | H9: 17 | I9: -0.8 | J9: =I9+G9 -> 15.52 | R9: 5600 | S9: 120 | T9: MCS0 | U9: 16 | V9: 15.41 | W9: 17 | X9: -4.2 | Y9: =X9+V9 -> 11.21 | AG9: 5785 | AH9: 157 | AI9: MCS0 | AJ9: 16 | AK9: 9.42 | AL9: 17 | AM9: -3.2 | AN9: =AM9+AK9 -> 6.22
C10: 5320 | D10: 64 | E10: MCS0 | F10: 16 | G10: 16.27 | H10: 17 | I10: -0.8 | J10: =I10+G10 -> 15.47 | R10: 5700 | S10: 140 | T10: MCS0 | U10: 16 | V10: 15.33 | W10: 17 | X10: -4.2 | Y10: =X10+V10 -> 11.13 | AG10: 5825 | AH10: 165 | AI10: MCS0 | AJ10: 16 | AK10: 9.79 | AL10: 17 | AM10: -3.2 | AN10: =AM10+AK10 -> 6.59
B11: 802.11n HT40 | C11: 5190 | D11: 38 | E11: MCS0 | F11: 16 | G11: 15.61 | H11: 17 | I11: -0.8 | J11: =I11+G11 -> 14.81 | Q11: 802.11n HT40 | R11: 5510 | S11: 102 | T11: MCS0 | U11: 16 | V11: 15.58 | W11: 17 | X11: -4.2 | Y11: =X11+V11 -> 11.38 | AF11: 802.11n HT40 | AG11: 5755 | AH11: 151 | AI11: MCS0 | AJ11: 16 | AK11: 9.27 | AL11: 17 | AM11: -3.2 | AN11: =AM11+AK11 -> 6.07
C12: 5270 | D12: 54 | E12: MCS0 | F12: 16 | G12: 14.3 | H12: 17 | I12: -0.8 | J12: =I12+G12 -> 13.5 | R12: 5590 | S12: 118 | T12: MCS0 | U12: 16 | V12: 14.39 | W12: 17 | X12: -4.2 | Y12: =X12+V12 -> 10.19 | AG12: 5795 | AH12: 159 | AI12: MCS0 | AJ12: 16 | AK12: 9.25 | AL12: 17 | AM12: -3.2 | AN12: =AM12+AK12 -> 6.05
C13: 5310 | D13: 62 | E13: MCS0 | F13: 16 | G13: 14.87 | H13: 17 | I13: -0.8 | J13: =I13+G13 -> 14.07 | R13: 5670 | S13: 134 | T13: MCS0 | U13: 16 | V13: 14.8 | W13: 17 | X13: -4.2 | Y13: =X13+V13 -> 10.6 | AF13: 802.11ac VHT20 | AG13: 5745 | AH13: 149 | AI13: MCS0 | AJ13: 16 | AK13: 9.6 | AL13: 17 | AM13: -3.2 | AN13: =AM13+AK13 -> 6.4
B14: 802.11ac VHT20 | C14: 5180 | D14: 36 | E14: MCS0 | F14: 16 | G14: 13.92 | H14: 17 | I14: -0.8 | J14: =I14+G14 -> 13.12 | Q14: 802.11ac VHT20 | R14: 5500 | S14: 100 | T14: MCS0 | U14: 16 | V14: 15.32 | W14: 17 | X14: -4.2 | Y14: =X14+V14 -> 11.12 | AG14: 5785 | AH14: 157 | AI14: MCS0 | AJ14: 16 | AK14: 9.58 | AL14: 17 | AM14: -3.2 | AN14: =AM14+AK14 -> 6.38
C15: 5260 | D15: 52 | E15: MCS0 | F15: 16 | G15: 16.25 | H15: 17 | I15: -0.8 | J15: =I15+G15 -> 15.45 | R15: 5600 | S15: 120 | T15: MCS0 | U15: 16 | V15: 15.4 | W15: 17 | X15: -4.2 | Y15: =X15+V15 -> 11.2 | AG15: 5825 | AH15: 165 | AI15: MCS0 | AJ15: 16 | AK15: 9.76 | AL15: 17 | AM15: -3.2 | AN15: =AM15+AK15 -> 6.56
C16: 5320 | D16: 64 | E16: MCS0 | F16: 16 | G16: 16.27 | H16: 17 | I16: -0.8 | J16: =I16+G16 -> 15.47 | R16: 5700 | S16: 140 | T16: MCS0 | U16: 16 | V16: 15.32 | W16: 17 | X16: -4.2 | Y16: =X16+V16 -> 11.12 | AF16: 802.11ac VHT40 | AG16: 5755 | AH16: 151 | AI16: MCS0 | AJ16: 16 | AK16: 9.56 | AL16: 17 | AM16: -3.2 | AN16: =AM16+AK16 -> 6.36
B17: 802.11ac VHT40 | C17: 5190 | D17: 38 | E17: MCS0 | F17: 16 | G17: 15.51 | H17: 17 | I17: -0.8 | J17: =I17+G17 -> 14.71 | Q17: 802.11ac VHT40 | R17: 5510 | S17: 102 | T17: MCS0 | U17: 16 | V17: 15.55 | W17: 17 | X17: -4.2 | Y17: =X17+V17 -> 11.35 | AG17: 5795 | AH17: 159 | AI17: MCS0 | AJ17: 16 | AK17: 9.31 | AL17: 17 | AM17: -3.2 | AN17: =AM17+AK17 -> 6.11
C18: 5270 | D18: 54 | E18: MCS0 | F18: 16 | G18: 14.41 | H18: 17 | I18: -0.8 | J18: =I18+G18 -> 13.61 | R18: 5590 | S18: 118 | T18: MCS0 | U18: 16 | V18: 14.28 | W18: 17 | X18: -4.2 | Y18: =X18+V18 -> 10.08 | AF18: 802.11ac VHT80 | AG18: 5775 | AH18: 155 | AI18: MCS0 | AJ18: 16 | AK18: 9.31 | AL18: 17 | AM18: -3.2 | AN18: =AM18+AK18 -> 6.11
C19: 5310 | D19: 62 | E19: MCS0 | F19: 16 | G19: 14.59 | H19: 17 | I19: -0.8 | J19: =I19+G19 -> 13.79 | R19: 5670 | S19: 134 | T19: MCS0 | U19: 16 | V19: 14.61 | W19: 17 | X19: -4.2 | Y19: =X19+V19 -> 10.41
B20: 802.11ac VHT80 | C20: 5210 | D20: 42 | E20: MCS0 | F20: 16 | G20: 13.9 | H20: 17 | I20: -0.8 | J20: =I20+G20 -> 13.1 | Q20: 802.11ac VHT80 | R20: 5530 | S20: 106 | T20: MCS0 | U20: 16 | V20: 15.13 | W20: 17 | X20: -4.2 | Y20: =X20+V20 -> 10.93
C21: 5290 | D21: 58 | E21: MCS0 | F21: 16 | G21: 13.49 | H21: 17 | I21: -0.8 | J21: =I21+G21 -> 12.69 | R21: 5610 | S21: 122 | T21: MCS0 | U21: 16 | V21: 13.43 | W21: 17 | X21: -4.2 | Y21: =X21+V21 -> 9.23
B22: 802.11ac VHT160 | C22: 5250 | D22: 50 | E22: MCS0 | F22: 16 | G22: 13.59 | H22: 17 | I22: -0.8 | J22: =I22+G22 -> 12.79 | Q22: 802.11ac VHT160 | R22: 5570 | S22: 114 | T22: MCS0 | U22: 16 | V22: 13.36 | W22: 17 | X22: -4.2 | Y22: =X22+V22 -> 9.16
B25: SISO (Antenna 2)
B26: 5.2 &5.3 GHz Legacy | Q26: 5.5 & 5.6 GHz Legacy | AF26: 5.8 GHz Legacy
B27: Mode | C27: Freq. | D27: Channel | E27: Data Rate | F27: PLS | G27: Average Power(㏈m) | H27: Tune-Up Power(㏈m) | I27: Peak Gain(dBi) | J27: E.I.R.P | Q27: Mode | R27: Freq. | S27: Channel | T27: Data Rate | U27: PLS | V27: Average Power(㏈m) | W27: Tune-Up Power(㏈m) | X27: Peak Gain(dBi) | Y27: E.I.R.P | AF27: Mode | AG27: Freq. | AH27: Channel | AI27: Data Rate | AJ27: PLS | AK27: Average Power(㏈m) | AL27: Tune-Up Power(㏈m) | AM27: Peak Gain(dBi) | AN27: E.I.R.P
B28: 802.11a | C28: 5180 | D28: 36 | E28: 6 | F28: 16 | G28: 16.35 | H28: 17 | I28: -1.2 | J28: =G28+I28 -> 15.15 | Q28: 802.11a | R28: 5500 | S28: 100 | T28: 6 | U28: 16 | V28: 15.85 | W28: 17 | X28: -1 | Y28: =V28+X28 -> 14.85 | AF28: 802.11a | AG28: 5745 | AH28: 149 | AI28: 6 | AJ28: 16 | AK28: 8.84 | AL28: 17 | AM28: -2.4 | AN28: =AK28+AM28 -> 6.44
C29: 5260 | D29: 52 | E29: 6 | F29: 16 | G29: 16.35 | H29: 17 | I29: -1.2 | J29: =G29+I29 -> 15.15 | R29: 5600 | S29: 120 | T29: 6 | U29: 16 | V29: 15.85 | W29: 17 | X29: -1 | Y29: =V29+X29 -> 14.85 | AG29: 5785 | AH29: 157 | AI29: 6 | AJ29: 16 | AK29: 8.42 | AL29: 17 | AM29: -2.4 | AN29: =AK29+AM29 -> 6.02
C30: 5320 | D30: 64 | E30: 6 | F30: 16 | G30: 15.93 | H30: 17 | I30: -1.2 | J30: =G30+I30 -> 14.73 | R30: 5700 | S30: 140 | T30: 6 | U30: 16 | V30: 15.98 | W30: 17 | X30: -1 | Y30: =V30+X30 -> 14.98 | AG30: 5825 | AH30: =AH7 -> 165 | AI30: 6 | AJ30: 16 | AK30: 8.23 | AL30: 17 | AM30: -2.4 | AN30: =AK30+AM30 -> 5.83
B31: 802.11n HT20 | C31: 5180 | D31: 36 | E31: MCS0 | F31: 16 | G31: 15.99 | H31: 17 | I31: -1.2 | J31: =G31+I31 -> 14.79 | Q31: 802.11n HT20 | R31: 5500 | S31: 100 | T31: MCS0 | U31: 16 | V31: 15.13 | W31: 17 | X31: -1 | Y31: =V31+X31 -> 14.13 | AF31: 802.11n HT20 | AG31: 5745 | AH31: 149 | AI31: MCS0 | AJ31: 16 | AK31: 8.83 | AL31: 17 | AM31: -2.4 | AN31: =AK31+AM31 -> 6.43
C32: 5260 | D32: 52 | E32: MCS0 | F32: 16 | G32: 16.44 | H32: 17 | I32: -1.2 | J32: =G32+I32 -> 15.24 | R32: 5600 | S32: 120 | T32: MCS0 | U32: 16 | V32: 16.09 | W32: 17 | X32: -1 | Y32: =V32+X32 -> 15.09 | AG32: 5785 | AH32: 157 | AI32: MCS0 | AJ32: 16 | AK32: 8.53 | AL32: 17 | AM32: -2.4 | AN32: =AK32+AM32 -> 6.13
C33: 5320 | D33: 64 | E33: MCS0 | F33: 16 | G33: 15.91 | H33: 17 | I33: -1.2 | J33: =G33+I33 -> 14.71 | R33: 5700 | S33: 140 | T33: MCS0 | U33: 16 | V33: 16.08 | W33: 17 | X33: -1 | Y33: =V33+X33 -> 15.08 | AG33: 5825 | AH33: =AH30 -> 165 | AI33: MCS0 | AJ33: 16 | AK33: 7.92 | AL33: 17 | AM33: -2.4 | AN33: =AK33+AM33 -> 5.52
B34: 802.11n HT40 | C34: 5190 | D34: 38 | E34: MCS0 | F34: 16 | G34: 16.15 | H34: 17 | I34: -1.2 | J34: =G34+I34 -> 14.95 | Q34: 802.11n HT40 | R34: 5510 | S34: 102 | T34: MCS0 | U34: 16 | V34: 15.57 | W34: 17 | X34: -1 | Y34: =V34+X34 -> 14.57 | AF34: 802.11n HT40 | AG34: 5755 | AH34: 151 | AI34: MCS0 | AJ34: 16 | AK34: 8.8 | AL34: 17 | AM34: -2.4 | AN34: =AK34+AM34 -> 6.4
C35: 5270 | D35: 54 | E35: MCS0 | F35: 16 | G35: 14.47 | H35: 17 | I35: -1.2 | J35: =G35+I35 -> 13.27 | R35: 5590 | S35: 118 | T35: MCS0 | U35: 16 | V35: 14.94 | W35: 17 | X35: -1 | Y35: =V35+X35 -> 13.94 | AG35: 5795 | AH35: 159 | AI35: MCS0 | AJ35: 16 | AK35: 8.33 | AL35: 17 | AM35: -2.4 | AN35: =AK35+AM35 -> 5.93
C36: 5310 | D36: 62 | E36: MCS0 | F36: 16 | G36: 14.32 | H36: 17 | I36: -1.2 | J36: =G36+I36 -> 13.12 | R36: 5670 | S36: 134 | T36: MCS0 | U36: 16 | V36: 14.88 | W36: 17 | X36: -1 | Y36: =V36+X36 -> 13.88 | AF36: 802.11ac VHT20 | AG36: 5745 | AH36: 149 | AI36: MCS0 | AJ36: 16 | AK36: 8.82 | AL36: 17 | AM36: -2.4 | AN36: =AK36+AM36 -> 6.42
B37: 802.11ac VHT20 | C37: 5180 | D37: 36 | E37: MCS0 | F37: 16 | G37: 14.37 | H37: 17 | I37: -1.2 | J37: =G37+I37 -> 13.17 | Q37: 802.11ac VHT20 | R37: 5500 | S37: 100 | T37: MCS0 | U37: 16 | V37: 14.79 | W37: 17 | X37: -1 | Y37: =V37+X37 -> 13.79 | AG37: 5785 | AH37: 157 | AI37: MCS0 | AJ37: 16 | AK37: 8.56 | AL37: 17 | AM37: -2.4 | AN37: =AK37+AM37 -> 6.16
C38: 5260 | D38: 52 | E38: MCS0 | F38: 16 | G38: 16.37 | H38: 17 | I38: -1.2 | J38: =G38+I38 -> 15.17 | R38: 5600 | S38: 120 | T38: MCS0 | U38: 16 | V38: 16 | W38: 17 | X38: -1 | Y38: =V38+X38 -> 15 | AG38: 5825 | AH38: =AH33 -> 165 | AI38: MCS0 | AJ38: 16 | AK38: 8.12 | AL38: 17 | AM38: -2.4 | AN38: =AK38+AM38 -> 5.72
C39: 5320 | D39: 64 | E39: MCS0 | F39: 16 | G39: 16.04 | H39: 17 | I39: -1.2 | J39: =G39+I39 -> 14.84 | R39: 5700 | S39: 140 | T39: MCS0 | U39: 16 | V39: 16.08 | W39: 17 | X39: -1 | Y39: =V39+X39 -> 15.08 | AF39: 802.11ac VHT40 | AG39: 5755 | AH39: 151 | AI39: MCS0 | AJ39: 16 | AK39: 8.83 | AL39: 17 | AM39: -2.4 | AN39: =AK39+AM39 -> 6.43
B40: 802.11ac VHT40 | C40: 5190 | D40: 38 | E40: MCS0 | F40: 16 | G40: 16.03 | H40: 17 | I40: -1.2 | J40: =G40+I40 -> 14.83 | Q40: 802.11ac VHT40 | R40: 5510 | S40: 102 | T40: MCS0 | U40: 16 | V40: 15.33 | W40: 17 | X40: -1 | Y40: =V40+X40 -> 14.33 | AG40: 5795 | AH40: 159 | AI40: MCS0 | AJ40: 16 | AK40: 8.26 | AL40: 17 | AM40: -2.4 | AN40: =AK40+AM40 -> 5.86
C41: 5270 | D41: 54 | E41: MCS0 | F41: 16 | G41: 13.93 | H41: 17 | I41: -1.2 | J41: =G41+I41 -> 12.73 | R41: 5590 | S41: 118 | T41: MCS0 | U41: 16 | V41: 15.42 | W41: 17 | X41: -1 | Y41: =V41+X41 -> 14.42 | AF41: 802.11ac VHT80 | AG41: 5775 | AH41: 155 | AI41: MCS0 | AJ41: 16 | AK41: 8.61 | AL41: 17 | AM41: -2.4 | AN41: =AK41+AM41 -> 6.21
C42: 5310 | D42: 62 | E42: MCS0 | F42: 16 | G42: 14.32 | H42: 17 | I42: -1.2 | J42: =G42+I42 -> 13.12 | R42: 5670 | S42: 134 | T42: MCS0 | U42: 16 | V42: 15.55 | W42: 17 | X42: -1 | Y42: =V42+X42 -> 14.55
...

Sheet WLAN 2.4 GHz 802.11ax Ant1
B2: SISO (Antenna 1)
B3: 2.4 GHz 802.11ax
B4: Mode | C4: Freq. (㎒) | D4: Channel | E4: Tone | F4: Worst RU | G4: Data Rate | H4: PLS | I4: Average Power(㏈m) | J4: Tune-Up Power(㏈m) | K4: Peak Gain (dBi) | L4: E.I.R.P
A5: Worst Data Rate | B5: 802.11ax HE20 | C5: 2412 | D5: 1 | E5: 26T | G5: =$A$6 -> 0 | H5: 9.5 | I5: 9.41 | J5: 10 | K5: -0.23 | L5: =K5+J5 -> 9.77
E6: 52T | G6: =$A$6 -> 0 | H6: 11.5 | I6: 11.25 | J6: 12 | K6: -0.23 | L6: =K6+J6 -> 11.77
E7: 106T | G7: =$A$6 -> 0 | H7: 14.5 | I7: 14.1 | J7: 15 | K7: -0.23 | L7: =K7+J7 -> 14.77
E8: 242T | G8: =$A$6 -> 0 | H8: 15.5 | I8: 15.46 | J8: 16 | K8: -0.23 | L8: =K8+J8 -> 15.77
E9: SU | F9: X | G9: =$A$6 -> 0 | H9: 15.5 | I9: 15.51 | J9: 16 | K9: -0.23 | L9: =K9+J9 -> 15.77
C10: 2442 | D10: 7 | E10: 26T | F10: =F5 -> 0 | G10: =$A$6 -> 0 | H10: 9.5 | I10: 9.01 | J10: 10 | K10: -0.23 | L10: =K10+J10 -> 9.77
E11: 52T | F11: =F6 -> 0 | G11: =$A$6 -> 0 | H11: 11.5 | I11: 11.04 | J11: 12 | K11: -0.23 | L11: =K11+J11 -> 11.77
E12: 106T | F12: =F7 -> 0 | G12: =$A$6 -> 0 | H12: 14.5 | I12: 14.02 | J12: 15 | K12: -0.23 | L12: =K12+J12 -> 14.77
E13: 242T | F13: =F8 -> 0 | G13: =$A$6 -> 0 | H13: 15.5 | I13: 15.06 | J13: 16 | K13: -0.23 | L13: =K13+J13 -> 15.77
E14: SU | F14: =F9 -> X | G14: =$A$6 -> 0 | H14: 15.5 | I14: 15.08 | J14: 16 | K14: -0.23 | L14: =K14+J14 -> 15.77
C15: 2472 | D15: 13 | E15: 26T | F15: =F10 -> 0 | G15: =$A$6 -> 0 | H15: 9.5 | I15: 9.66 | J15: 10 | K15: -0.23 | L15: =K15+J15 -> 9.77
E16: 52T | F16: =F11 -> 0 | G16: =$A$6 -> 0 | H16: 11.5 | I16: 11.34 | J16: 12 | K16: -0.23 | L16: =K16+J16 -> 11.77
E17: 106T | F17: =F12 -> 0 | G17: =$A$6 -> 0 | H17: 14.5 | I17: 14.04 | J17: 15 | K17: -0.23 | L17: =K17+J17 -> 14.77
E18: 242T | F18: =F13 -> 0 | G18: =$A$6 -> 0 | H18: 15.5 | I18: 15.37 | J18: 16 | K18: -0.23 | L18: =K18+J18 -> 15.77
E19: SU | F19: =F14 -> X | G19: =$A$6 -> 0 | H19: 15.5 | I19: 15.39 | J19: 16 | K19: -0.23 | L19: =K19+J19 -> 15.77
A20: Worst Data Rate | B20: 802.11ax HE40 | C20: 2422 | D20: 3 | E20: 26T | G20: =$A$21 -> 0 | H20: 9.5 | I20: 9.8992331 | J20: 10 | K20: -0.23 | L20: =K20+J20 -> 9.77
E21: 52T | G21: =$A$21 -> 0 | H21: 11.5 | I21: 11.943919 | J21: 12 | K21: -0.23 | L21: =K21+J21 -> 11.77
E22: 106T | G22: =$A$21 -> 0 | H22: 14.5 | I22: 14.412845 | J22: 15 | K22: -0.23 | L22: =K22+J22 -> 14.77
E23: 242T | G23: =$A$21 -> 0 | H23: 15.5 | I23: 16.450256 | J23: 16 | K23: -0.23 | L23: =K23+J23 -> 15.77
E24: 484T | G24: =$A$21 -> 0 | H24: 15.5 | I24: 15.882616 | J24: 16 | K24: -0.23 | L24: =K24+J24 -> 15.77
E25: SU | F25: X | G25: =$A$21 -> 0 | H25: 9.5 | I25: 9.1517264 | J25: 10 | K25: -0.23 | L25: =K25+J25 -> 9.77
C26: 2442 | D26: 7 | E26: 26T | F26: =F20 -> 0 | G26: =$A$21 -> 0 | H26: 11.5 | I26: 11.765109 | J26: 12 | K26: -0.23 | L26: =K26+J26 -> 11.77
E27: 52T | F27: =F21 -> 0 | G27: =$A$21 -> 0 | H27: 14.5 | I27: 14.093258 | J27: 15 | K27: -0.23 | L27: =K27+J27 -> 14.77
E28: 106T | F28: =F22 -> 0 | G28: =$A$21 -> 0 | H28: 15.5 | I28: 15.486762 | J28: 16 | K28: -0.23 | L28: =K28+J28 -> 15.77
E29: 242T | F29: =F23 -> 0 | G29: =$A$21 -> 0 | H29: 15.5 | I29: 15.552279 | J29: 16 | K29: -0.23 | L29: =K29+J29 -> 15.77
E30: 484T | F30: =F24 -> 0 | G30: =$A$21 -> 0 | H30: 9.5 | I30: 10.532604 | J30: 10 | K30: -0.23 | L30: =K30+J30 -> 9.77
E31: SU | F31: =F25 -> X | G31: =$A$21 -> 0 | H31: 11.5 | I31: 11.588255 | J31: 12 | K31: -0.23 | L31: =K31+J31 -> 11.77
C32: 2462 | D32: 11 | E32: 26T | F32: =F26 -> 0 | G32: =$A$21 -> 0 | H32: 14.5 | I32: 14.645668 | J32: 15 | K32: -0.23 | L32: =K32+J32 -> 14.77
E33: 52T | F33: =F27 -> 0 | G33: =$A$21 -> 0 | H33: 15.5 | I33: 15.609135 | J33: 16 | K33: -0.23 | L33: =K33+J33 -> 15.77
E34: 106T | F34: =F28 -> 0 | G34: =$A$21 -> 0 | H34: 15.5 | I34: 16.572603 | J34: 16 | K34: -0.23 | L34: =K34+J34 -> 15.77
E35: 242T | F35: =F29 -> 0 | G35: =$A$21 -> 0 | H35: 15.5 | I35: 17.53607 | J35: 16 | K35: -0.23 | L35: =K35+J35 -> 15.77
E36: 484T | F36: =F30 -> 0 | G36: =$A$21 -> 0 | H36: 15.5 | I36: 18.499538 | J36: 16 | K36: -0.23 | L36: =K36+J36 -> 15.77
E37: SU | F37: =F31 -> X | G37: =$A$21 -> 0 | H37: 15.5 | I37: 19.463005 | J37: 16 | K37: -0.23 | L37: =K37+J37 -> 15.77

Sheet WLAN 2.4 GHz 802.11ax Ant2
B2: SISO (Antenna 2)
B3: 2.4 GHz 802.11ax
B4: Mode | C4: Freq. (㎒) | D4: Channel | E4: Tone | F4: Worst RU | G4: Data Rate | H4: PLS | I4: Average Power(㏈m) | J4: Tune-Up Power(㏈m) | K4: Peak Gain (dBi) | L4: E.I.R.P
A5: Worst Data Rate | B5: 802.11ax HE20 | C5: 2412 | D5: 1 | E5: 26T | F5: ='WLAN 2.4 GHz 802.11ax Ant1'!F5 -> 0 | G5: =$A$6 -> 0 | H5: 9.5 | I5: 9.23 | J5: 10 | K5: -0.26 | L5: =K5+J5 -> 9.74
A6: ='WLAN 2.4 GHz 802.11ax Ant1'!A6 -> 0 | E6: 52T | F6: ='WLAN 2.4 GHz 802.11ax Ant1'!F6 -> 0 | G6: =$A$6 -> 0 | H6: 11.5 | I6: 11.55 | J6: 12 | K6: -0.26 | L6: =K6+J6 -> 11.74
E7: 106T | F7: ='WLAN 2.4 GHz 802.11ax Ant1'!F7 -> 0 | G7: =$A$6 -> 0 | H7: 14.5 | I7: 14.51 | J7: 15 | K7: -0.26 | L7: =K7+J7 -> 14.74
E8: 242T | F8: ='WLAN 2.4 GHz 802.11ax Ant1'!F8 -> 0 | G8: =$A$6 -> 0 | H8: 15.5 | I8: 15.38 | J8: 16 | K8: -0.26 | L8: =K8+J8 -> 15.74
E9: SU | F9: ='WLAN 2.4 GHz 802.11ax Ant1'!F9 -> X | G9: =$A$6 -> 0 | H9: 15.5 | I9: 15.39 | J9: 16 | K9: -0.26 | L9: =K9+J9 -> 15.74
C10: 2442 | D10: 7 | E10: 26T | F10: ='WLAN 2.4 GHz 802.11ax Ant1'!F10 -> 0 | G10: =$A$6 -> 0 | H10: 9.5 | I10: 9 | J10: 10 | K10: -0.26 | L10: =K10+J10 -> 9.74
E11: 52T | F11: ='WLAN 2.4 GHz 802.11ax Ant1'!F11 -> 0 | G11: =$A$6 -> 0 | H11: 11.5 | I11: 11.06 | J11: 12 | K11: -0.26 | L11: =K11+J11 -> 11.74
E12: 106T | F12: ='WLAN 2.4 GHz 802.11ax Ant1'!F12 -> 0 | G12: =$A$6 -> 0 | H12: 14.5 | I12: 14.27 | J12: 15 | K12: -0.26 | L12: =K12+J12 -> 14.74
E13: 242T | F13: ='WLAN 2.4 GHz 802.11ax Ant1'!F13 -> 0 | G13: =$A$6 -> 0 | H13: 15.5 | I13: 15.04 | J13: 16 | K13: -0.26 | L13: =K13+J13 -> 15.74
E14: SU | F14: ='WLAN 2.4 GHz 802.11ax Ant1'!F14 -> X | G14: =$A$6 -> 0 | H14: 15.5 | I14: 15.07 | J14: 16 | K14: -0.26 | L14: =K14+J14 -> 15.74
C15: 2472 | D15: 13 | E15: 26T | F15: ='WLAN 2.4 GHz 802.11ax Ant1'!F15 -> 0 | G15: =$A$6 -> 0 | H15: 9.5 | I15: 9.42 | J15: 10 | K15: -0.26 | L15: =K15+J15 -> 9.74
E16: 52T | F16: ='WLAN 2.4 GHz 802.11ax Ant1'!F16 -> 0 | G16: =$A$6 -> 0 | H16: 11.5 | I16: 11.03 | J16: 12 | K16: -0.26 | L16: =K16+J16 -> 11.74
E17: 106T | F17: ='WLAN 2.4 GHz 802.11ax Ant1'!F17 -> 0 | G17: =$A$6 -> 0 | H17: 14.5 | I17: 14.03 | J17: 15 | K17: -0.26 | L17: =K17+J17 -> 14.74
E18: 242T | F18: ='WLAN 2.4 GHz 802.11ax Ant1'!F18 -> 0 | G18: =$A$6 -> 0 | H18: 15.5 | I18: 15.15 | J18: 16 | K18: -0.26 | L18: =K18+J18 -> 15.74
E19: SU | F19: ='WLAN 2.4 GHz 802.11ax Ant1'!F19 -> X | G19: =$A$6 -> 0 | H19: 15.5 | I19: 15.17 | J19: 16 | K19: -0.26 | L19: =K19+J19 -> 15.74
A20: Worst Data Rate | B20: 802.11ax HE40 | C20: 2422 | D20: 3 | E20: 26T | F20: ='WLAN 2.4 GHz 802.11ax Ant1'!F20 -> 0 | G20: =$A$21 -> 0 | H20: 9.5 | I20: 9.6096001 | J20: 10 | K20: -0.26 | L20: =K20+J20 -> 9.74
A21: ='WLAN 2.4 GHz 802.11ax Ant1'!A21 -> 0 | E21: 52T | F21: ='WLAN 2.4 GHz 802.11ax Ant1'!F21 -> 0 | G21: =$A$21 -> 0 | H21: 11.5 | I21: 12.502562 | J21: 12 | K21: -0.26 | L21: =K21+J21 -> 11.74
E22: 106T | F22: ='WLAN 2.4 GHz 802.11ax Ant1'!F22 -> 0 | G22: =$A$21 -> 0 | H22: 14.5 | I22: 15.496336 | J22: 15 | K22: -0.26 | L22: =K22+J22 -> 14.74
E23: 242T | F23: ='WLAN 2.4 GHz 802.11ax Ant1'!F23 -> 0 | G23: =$A$21 -> 0 | H23: 15.5 | I23: 15.784715 | J23: 16 | K23: -0.26 | L23: =K23+J23 -> 15.74
E24: 484T | F24: ='WLAN 2.4 GHz 802.11ax Ant1'!F24 -> 0 | G24: =$A$21 -> 0 | H24: 15.5 | I24: 15.91936 | J24: 16 | K24: -0.26 | L24: =K24+J24 -> 15.74
E25: SU | F25: ='WLAN 2.4 GHz 802.11ax Ant1'!F25 -> X | G25: =$A$21 -> 0 | H25: 9.5 | I25: 9.7223286 | J25: 10 | K25: -0.26 | L25: =K25+J25 -> 9.74
C26: 2442 | D26: 7 | E26: 26T | F26: ='WLAN 2.4 GHz 802.11ax Ant1'!F26 -> 0 | G26: =$A$21 -> 0 | H26: 11.5 | I26: 11.926783 | J26: 12 | K26: -0.26 | L26: =K26+J26 -> 11.74
E27: 52T | F27: ='WLAN 2.4 GHz 802.11ax Ant1'!F27 -> 0 | G27: =$A$21 -> 0 | H27: 14.5 | I27: 15.185898 | J27: 15 | K27: -0.26 | L27: =K27+J27 -> 14.74
E28: 106T | F28: ='WLAN 2.4 GHz 802.11ax Ant1'!F28 -> 0 | G28: =$A$21 -> 0 | H28: 15.5 | I28: 15.90912 | J28: 16 | K28: -0.26 | L28: =K28+J28 -> 15.74
E29: 242T | F29: ='WLAN 2.4 GHz 802.11ax Ant1'!F29 -> 0 | G29: =$A$21 -> 0 | H29: 15.5 | I29: 15.347989 | J29: 16 | K29: -0.26 | L29: =K29+J29 -> 15.74
E30: 484T | F30: ='WLAN 2.4 GHz 802.11ax Ant1'!F30 -> 0 | G30: =$A$21 -> 0 | H30: 9.5 | I30: 9.9799802 | J30: 10 | K30: -0.26 | L30: =K30+J30 -> 9.74
E31: SU | F31: ='WLAN 2.4 GHz 802.11ax Ant1'!F31 -> X | G31: =$A$21 -> 0 | H31: 11.5 | I31: 11.540971 | J31: 12 | K31: -0.26 | L31: =K31+J31 -> 11.74
C32: 2462 | D32: 11 | E32: 26T | F32: ='WLAN 2.4 GHz 802.11ax Ant1'!F32 -> 0 | G32: =$A$21 -> 0 | H32: 14.5 | I32: 14.29082 | J32: 15 | K32: -0.26 | L32: =K32+J32 -> 14.74
E33: 52T | F33: ='WLAN 2.4 GHz 802.11ax Ant1'!F33 -> 0 | G33: =$A$21 -> 0 | H33: 15.5 | I33: 15.984144 | J33: 16 | K33: -0.26 | L33: =K33+J33 -> 15.74
E34: 106T | F34: ='WLAN 2.4 GHz 802.11ax Ant1'!F34 -> 0 | G34: =$A$21 -> 0 | H34: 15.5 | I34: 15.807577 | J34: 16 | K34: -0.26 | L34: =K34+J34 -> 15.74
E35: 242T | F35: ='WLAN 2.4 GHz 802.11ax Ant1'!F35 -> 0 | G35: =$A$21 -> 0 | H35: 15.5 | I35: 15.347989 | J35: 15 | K35: -0.26 | L35: =K35+J35 -> 14.74
E36: 484T | F36: ='WLAN 2.4 GHz 802.11ax Ant1'!F36 -> 0 | G36: =$A$21 -> 0 | H36: 15.5 | I36: 9.9799802 | J36: 16 | K36: -0.26 | L36: =K36+J36 -> 15.74
E37: SU | F37: ='WLAN 2.4 GHz 802.11ax Ant1'!F37 -> X | G37: =$A$21 -> 0 | H37: 15.5 | I37: 11.540971 | J37: 16 | K37: -0.26 | L37: =K37+J37 -> 15.74

Sheet WLAN 2.4 GHz 802.11ax Ant1+2
B2: MIMO (Antenna 1 + Antenna 2)
B3: 2.4 GHz 802.11ax
B4: Mode | C4: Freq. (㎒) | D4: Channel | E4: Tone | F4: Worst RU | G4: Data Rate | H4: Ant.1 PLS | I4: Ant.2 PLS | J4: Ant.1 Average Power(㏈m) | K4: Ant.2 Average Power(㏈m) | L4: Tune-Up Power(㏈m) | M4: Ant.1+Ant.2 Average Power(㏈m) | N4: Tune-Up Power(㏈m) | O4: Peak Gain(dBi) | P4: E.I.R.P
A5: Worst Data Rate | B5: 802.11ax HE20 | C5: 2412 | D5: 1 | E5: 26T | F5: ='WLAN 2.4 GHz 802.11ax Ant1'!F5 -> 0 | G5: =$A$6 -> 0 | H5: 7 | I5: 7 | J5: 10.22 | K5: 10.22 | L5: 10 | M5: =10*LOG10((10^(J5/10))+(10^(K5/10))) -> 13.2303 | N5: =10*LOG10((10^(L5/10))*2) -> 13.0103 | O5: -0.65 | P5: =O5+N5 -> 12.3603
E6: 52T | F6: ='WLAN 2.4 GHz 802.11ax Ant1'!F6 -> 0 | G6: =$A$6 -> 0 | H6: 9 | I6: 9 | J6: 11.81 | K6: 11.81 | L6: 12 | M6: =10*LOG10((10^(J6/10))+(10^(K6/10))) -> 14.8203 | N6: =10*LOG10((10^(L6/10))*2) -> 15.0103 | O6: -0.65 | P6: =O6+N6 -> 14.3603
E7: 106T | F7: ='WLAN 2.4 GHz 802.11ax Ant1'!F7 -> 0 | G7: =$A$6 -> 0 | H7: 12 | I7: 12 | J7: 15.72 | K7: 15.72 | L7: 15 | M7: =10*LOG10((10^(J7/10))+(10^(K7/10))) -> 18.7303 | N7: =10*LOG10((10^(L7/10))*2) -> 18.0103 | O7: -0.65 | P7: =O7+N7 -> 17.3603
E8: 242T | F8: ='WLAN 2.4 GHz 802.11ax Ant1'!F8 -> 0 | G8: =$A$6 -> 0 | H8: 13 | I8: 13 | J8: 16.61 | K8: 16.61 | L8: 16 | M8: =10*LOG10((10^(J8/10))+(10^(K8/10))) -> 19.6203 | N8: =10*LOG10((10^(L8/10))*2) -> 19.0103 | O8: -0.65 | P8: =O8+N8 -> 18.3603
E9: SU | F9: ='WLAN 2.4 GHz 802.11ax Ant1'!F9 -> X | G9: =$A$6 -> 0 | H9: 15.5 | I9: 15.5 | J9: 18.74 | K9: 18.74 | L9: 19 | M9: =10*LOG10((10^(J9/10))+(10^(K9/10))) -> 21.7503 | N9: =10*LOG10((10^(L9/10))*2) -> 22.0103 | O9: -0.65 | P9: =O9+N9 -> 21.3603
C10: 2442 | D10: 7 | E10: 26T | F10: ='WLAN 2.4 GHz 802.11ax Ant1'!F10 -> 0 | G10: =$A$6 -> 0 | H10: 7 | I10: 7 | J10: 9.17 | K10: 9.17 | L10: 10 | M10: =10*LOG10((10^(J10/10))+(10^(K10/10))) -> 12.1803 | N10: =10*LOG10((10^(L10/10))*2) -> 13.0103 | O10: -0.65 | P10: =O10+N10 -> 12.3603
E11: 52T | F11: ='WLAN 2.4 GHz 802.11ax Ant1'!F11 -> 0 | G11: =$A$6 -> 0 | H11: 9 | I11: 9 | J11: 11.26 | K11: 11.26 | L11: 12 | M11: =10*LOG10((10^(J11/10))+(10^(K11/10))) -> 14.2703 | N11: =10*LOG10((10^(L11/10))*2) -> 15.0103 | O11: -0.65 | P11: =O11+N11 -> 14.3603
E12: 106T | F12: ='WLAN 2.4 GHz 802.11ax Ant1'!F12 -> 0 | G12: =$A$6 -> 0 | H12: 12 | I12: 12 | J12: 15.61 | K12: 15.61 | L12: 15 | M12: =10*LOG10((10^(J12/10))+(10^(K12/10))) -> 18.6203 | N12: =10*LOG10((10^(L12/10))*2) -> 18.0103 | O12: -0.65 | P12: =O12+N12 -> 17.3603
E13: 242T | F13: ='WLAN 2.4 GHz 802.11ax Ant1'!F13 -> 0 | G13: =$A$6 -> 0 | H13: 13 | I13: 13 | J13: 16.5 | K13: 16.5 | L13: 16 | M13: =10*LOG10((10^(J13/10))+(10^(K13/10))) -> 19.5103 | N13: =10*LOG10((10^(L13/10))*2) -> 19.0103 | O13: -0.65 | P13: =O13+N13 -> 18.3603
E14: SU | F14: ='WLAN 2.4 GHz 802.11ax Ant1'!F14 -> X | G14: =$A$6 -> 0 | H14: 15.5 | I14: 15.5 | J14: 18.25 | K14: 18.25 | L14: 19 | M14: =10*LOG10((10^(J14/10))+(10^(K14/10))) -> 21.2603 | N14: =10*LOG10((10^(L14/10))*2) -> 22.0103 | O14: -0.65 | P14: =O14+N14 -> 21.3603
C15: 2472 | D15: 13 | E15: 26T | F15: ='WLAN 2.4 GHz 802.11ax Ant1'!F15 -> 0 | G15: =$A$6 -> 0 | H15: 7 | I15: 7 | J15: 10.27 | K15: 10.27 | L15: 10 | M15: =10*LOG10((10^(J15/10))+(10^(K15/10))) -> 13.2803 | N15: =10*LOG10((10^(L15/10))*2) -> 13.0103 | O15: -0.65 | P15: =O15+N15 -> 12.3603
E16: 52T | F16: ='WLAN 2.4 GHz 802.11ax Ant1'!F16 -> 0 | G16: =$A$6 -> 0 | H16: 9 | I16: 9 | J16: 11.84 | K16: 11.84 | L16: 12 | M16: =10*LOG10((10^(J16/10))+(10^(K16/10))) -> 14.8503 | N16: =10*LOG10((10^(L16/10))*2) -> 15.0103 | O16: -0.65 | P16: =O16+N16 -> 14.3603
E17: 106T | F17: ='WLAN 2.4 GHz 802.11ax Ant1'!F17 -> 0 | G17: =$A$6 -> 0 | H17: 12 | I17: 12 | J17: 14.89 | K17: 14.89 | L17: 15 | M17: =10*LOG10((10^(J17/10))+(10^(K17/10))) -> 17.9003 | N17: =10*LOG10((10^(L17/10))*2) -> 18.0103 | O17: -0.65 | P17: =O17+N17 -> 17.3603
E18: 242T | F18: ='WLAN 2.4 GHz 802.11ax Ant1'!F18 -> 0 | G18: =$A$6 -> 0 | H18: 13 | I18: 13 | J18: 16.42 | K18: 16.42 | L18: 16 | M18: =10*LOG10((10^(J18/10))+(10^(K18/10))) -> 19.4303 | N18: =10*LOG10((10^(L18/10))*2) -> 19.0103 | O18: -0.65 | P18: =O18+N18 -> 18.3603
E19: SU | F19: ='WLAN 2.4 GHz 802.11ax Ant1'!F19 -> X | G19: =$A$6 -> 0 | H19: 15.5 | I19: 15.5 | J19: 18.4 | K19: 18.4 | L19: 19 | M19: =10*LOG10((10^(J19/10))+(10^(K19/10))) -> 21.4103 | N19: =10*LOG10((10^(L19/10))*2) -> 22.0103 | O19: -0.65 | P19: =O19+N19 -> 21.3603
A20: Worst Data Rate | B20: 802.11ax HE40 | C20: 2422 | D20: 3 | E20: 26T | F20: ='WLAN 2.4 GHz 802.11ax Ant1'!F20 -> 0 | G20: =$A$21 -> 0 | H20: 7 | I20: 7 | J20: 10.564005 | K20: 11.060767 | L20: 10 | M20: =10*LOG10((10^(J20/10))+(10^(K20/10))) -> 13.829785 | N20: =10*LOG10((10^(L20/10))*2) -> 13.0103 | O20: -0.65 | P20: =O20+N20 -> 12.3603
E21: 52T | F21: ='WLAN 2.4 GHz 802.11ax Ant1'!F21 -> 0 | G21: =$A$21 -> 0 | H21: 9 | I21: 9 | J21: 12.012013 | K21: 11.81607 | L21: 12 | M21: =10*LOG10((10^(J21/10))+(10^(K21/10))) -> 14.925447 | N21: =10*LOG10((10^(L21/10))*2) -> 15.0103 | O21: -0.65 | P21: =O21+N21 -> 14.3603
E22: 106T | F22: ='WLAN 2.4 GHz 802.11ax Ant1'!F22 -> 0 | G22: =$A$21 -> 0 | H22: 12 | I22: 12 | J22: 15.9413 | K22: 16.369842 | L22: 15 | M22: =10*LOG10((10^(J22/10))+(10^(K22/10))) -> 19.171155 | N22: =10*LOG10((10^(L22/10))*2) -> 18.0103 | O22: -0.65 | P22: =O22+N22 -> 17.3603
E23: 242T | F23: ='WLAN 2.4 GHz 802.11ax Ant1'!F23 -> 0 | G23: =$A$21 -> 0 | H23: 13 | I23: 13 | J23: 17.02299 | K23: 17.037782 | L23: 16 | M23: =10*LOG10((10^(J23/10))+(10^(K23/10))) -> 20.040692 | N23: =10*LOG10((10^(L23/10))*2) -> 19.0103 | O23: -0.65 | P23: =O23+N23 -> 18.3603
E24: 484T | F24: ='WLAN 2.4 GHz 802.11ax Ant1'!F24 -> 0 | G24: =$A$21 -> 0 | H24: 15.5 | I24: 15.5 | J24: 19.637942 | K24: 19.435781 | L24: 19 | M24: =10*LOG10((10^(J24/10))+(10^(K24/10))) -> 22.548338 | N24: =10*LOG10((10^(L24/10))*2) -> 22.0103 | O24: -0.65 | P24: =O24+N24 -> 21.3603
E25: SU | F25: ='WLAN 2.4 GHz 802.11ax Ant1'!F25 -> X | G25: =$A$21 -> 0 | H25: 7 | I25: 7 | J25: 10.024232 | K25: 9.5088017 | L25: 10 | M25: =10*LOG10((10^(J25/10))+(10^(K25/10))) -> 12.784459 | N25: =10*LOG10((10^(L25/10))*2) -> 13.0103 | O25: -0.65 | P25: =O25+N25 -> 12.3603
C26: 2442 | D26: 7 | E26: 26T | F26: ='WLAN 2.4 GHz 802.11ax Ant1'!F26 -> 0 | G26: =$A$21 -> 0 | H26: 9 | I26: 9 | J26: 11.800548 | K26: 11.329854 | L26: 12 | M26: =10*LOG10((10^(J26/10))+(10^(K26/10))) -> 14.581875 | N26: =10*LOG10((10^(L26/10))*2) -> 15.0103 | O26: -0.65 | P26: =O26+N26 -> 14.3603
E27: 52T | F27: ='WLAN 2.4 GHz 802.11ax Ant1'!F27 -> 0 | G27: =$A$21 -> 0 | H27: 12 | I27: 12 | J27: 15.889698 | K27: 16.023461 | L27: 15 | M27: =10*LOG10((10^(J27/10))+(10^(K27/10))) -> 18.967394 | N27: =10*LOG10((10^(L27/10))*2) -> 18.0103 | O27: -0.65 | P27: =O27+N27 -> 17.3603
E28: 106T | F28: ='WLAN 2.4 GHz 802.11ax Ant1'!F28 -> 0 | G28: =$A$21 -> 0 | H28: 13 | I28: 13 | J28: 17.04383 | K28: 17.225027 | L28: 16 | M28: =10*LOG10((10^(J28/10))+(10^(K28/10))) -> 20.145673 | N28: =10*LOG10((10^(L28/10))*2) -> 19.0103 | O28: -0.65 | P28: =O28+N28 -> 18.3603
E29: 242T | F29: ='WLAN 2.4 GHz 802.11ax Ant1'!F29 -> 0 | G29: =$A$21 -> 0 | H29: 15.5 | I29: 15.5 | J29: 18.980413 | K29: 18.837139 | L29: 19 | M29: =10*LOG10((10^(J29/10))+(10^(K29/10))) -> 21.919667 | N29: =10*LOG10((10^(L29/10))*2) -> 22.0103 | O29: -0.65 | P29: =O29+N29 -> 21.3603
E30: 484T | F30: ='WLAN 2.4 GHz 802.11ax Ant1'!F30 -> 0 | G30: =$A$21 -> 0 | H30: 7 | I30: 7 | J30: 11.130457 | K30: 10.309226 | L30: 10 | M30: =10*LOG10((10^(J30/10))+(10^(K30/10))) -> 13.749524 | N30: =10*LOG10((10^(L30/10))*2) -> 13.0103 | O30: -0.65 | P30: =O30+N30 -> 12.3603
E31: SU | F31: ='WLAN 2.4 GHz 802.11ax Ant1'!F31 -> X | G31: =$A$21 -> 0 | H31: 9 | I31: 9 | J31: 12.360374 | K31: 12.4064 | L31: 12 | M31: =10*LOG10((10^(J31/10))+(10^(K31/10))) -> 15.393748 | N31: =10*LOG10((10^(L31/10))*2) -> 15.0103 | O31: -0.65 | P31: =O31+N31 -> 14.3603
C32: 2462 | D32: 11 | E32: 26T | F32: ='WLAN 2.4 GHz 802.11ax Ant1'!F32 -> 0 | G32: =$A$21 -> 0 | H32: 12 | I32: 12 | J32: 15.791553 | K32: 15.506171 | L32: 15 | M32: =10*LOG10((10^(J32/10))+(10^(K32/10))) -> 18.661505 | N32: =10*LOG10((10^(L32/10))*2) -> 18.0103 | O32: -0.65 | P32: =O32+N32 -> 17.3603
E33: 52T | F33: ='WLAN 2.4 GHz 802.11ax Ant1'!F33 -> 0 | G33: =$A$21 -> 0 | H33: 13 | I33: 13 | J33: 17.200378 | K33: 16.929065 | L33: 16 | M33: =10*LOG10((10^(J33/10))+(10^(K33/10))) -> 20.07714 | N33: =10*LOG10((10^(L33/10))*2) -> 19.0103 | O33: -0.65 | P33: =O33+N33 -> 18.3603
E34: 106T | F34: ='WLAN 2.4 GHz 802.11ax Ant1'!F34 -> 0 | G34: =$A$21 -> 0 | H34: 15.5 | I34: 15.5 | J34: 18.545912 | K34: 18.632398 | L34: 19 | M34: =10*LOG10((10^(J34/10))+(10^(K34/10))) -> 21.59967 | N34: =10*LOG10((10^(L34/10))*2) -> 22.0103 | O34: -0.65 | P34: =O34+N34 -> 21.3603
E35: 242T | F35: ='WLAN 2.4 GHz 802.11ax Ant1'!F35 -> 0 | G35: =$A$21 -> 0 | H35: 15.5 | I35: 15.5 | J35: 18.545912 | K35: 18.632398 | L35: 20 | M35: =10*LOG10((10^(J35/10))+(10^(K35/10))) -> 21.59967 | N35: =10*LOG10((10^(L35/10))*2) -> 23.0103 | O35: -0.65 | P35: =O35+N35 -> 22.3603
E36: 484T | F36: ='WLAN 2.4 GHz 802.11ax Ant1'!F36 -> 0 | G36: =$A$21 -> 0 | H36: 15.5 | I36: 15.5 | J36: 18.545912 | K36: 18.632398 | L36: 21 | M36: =10*LOG10((10^(J36/10))+(10^(K36/10))) -> 21.59967 | N36: =10*LOG10((10^(L36/10))*2) -> 24.0103 | O36: -0.65 | P36: =O36+N36 -> 23.3603
E37: SU | F37: ='WLAN 2.4 GHz 802.11ax Ant1'!F37 -> X | G37: =$A$21 -> 0 | H37: 15.5 | I37: 15.5 | J37: 18.545912 | K37: 18.632398 | L37: 22 | M37: =10*LOG10((10^(J37/10))+(10^(K37/10))) -> 21.59967 | N37: =10*LOG10((10^(L37/10))*2) -> 25.0103 | O37: -0.65 | P37: =O37+N37 -> 24.3603

Sheet WLAN 5 GHz 802.11ax Ant1
B2: SISO (Antenna 1)
B3: 5.2 GHz 802.11ax | O3: 5.5 GHz 802.11ax | AB3: 5.8 GHz 802.11ax
B4: Mode | C4: Freq. (㎒) | D4: Channel | E4: Tone | F4: Worst RU | G4: Data Rate | H4: PLS | I4: Average Power(㏈m) | J4: Tune-Up Power(㏈m) | K4: Peak Gain (dBi) | L4: E.I.R.P | O4: Mode | P4: Freq. (㎒) | Q4: Channel | R4: Tone | S4: Worst RU | T4: Data Rate | U4: PLS | V4: Average Power(㏈m) | W4: Tune-Up Power(㏈m) | X4: Peak Gain (dBi) | Y4: E.I.R.P | AB4: Mode | AC4: Freq. (㎒) | AD4: Channel | AE4: Tone | AF4: Worst RU | AG4: Data Rate | AH4: PLS | AI4: Average Power(㏈m) | AJ4: Tune-Up Power(㏈m) | AK4: Peak Gain (dBi) | AL4: E.I.R.P
A5: Worst Data Rate | B5: 802.11ax HE20 | C5: 5180 | D5: 36 | E5: 26T | G5: =$A$6 -> 0 | H5: 9.5 | I5: 9.17 | J5: 10 | K5: -0.3 | L5: =J5+K5 -> 9.7 | N5: Worst Data Rate | O5: 802.11ax HE20 | P5: 5500 | Q5: 100 | R5: 26T | S5: =F5 -> 0 | T5: =$N$6 -> 0 | U5: 9.5 | V5: 9.4850239 | W5: 10 | X5: -0.54 | Y5: =W5+X5 -> 9.46 | AA5: Worst Data Rate | AB5: 802.11ax HE20 | AC5: 5745 | AD5: 149 | AE5: 26T | AG5: =$AA$6 -> 0 | AH5: 9.5 | AI5: 9.8204344 | AJ5: 10 | AK5: -0.12 | AL5: =AJ5+AK5 -> 9.88
E6: 52T | G6: =$A$6 -> 0 | H6: 11.5 | I6: 11.02 | J6: 12 | K6: -0.3 | L6: =J6+K6 -> 11.7 | R6: 52T | S6: =F6 -> 0 | T6: =$N$6 -> 0 | U6: 11.5 | V6: 12.019137 | W6: 12 | X6: -0.54 | Y6: =W6+X6 -> 11.46 | AE6: 52T | AG6: =$AA$6 -> 0 | AH6: 11.5 | AI6: 11.369646 | AJ6: 12 | AK6: -0.12 | AL6: =AJ6+AK6 -> 11.88
E7: 106T | G7: =$A$6 -> 0 | H7: 14.5 | I7: 14.16 | J7: 15 | K7: -0.3 | L7: =J7+K7 -> 14.7 | R7: 106T | S7: =F7 -> 0 | T7: =$N$6 -> 0 | U7: 14.5 | V7: 14.726063 | W7: 15 | X7: -0.54 | Y7: =W7+X7 -> 14.46 | AE7: 106T | AG7: =$AA$6 -> 0 | AH7: 14.5 | AI7: 14.219703 | AJ7: 15 | AK7: -0.12 | AL7: =AJ7+AK7 -> 14.88
E8: 242T | G8: =$A$6 -> 0 | H8: 15.5 | I8: 15.53 | J8: 16 | K8: -0.3 | L8: =J8+K8 -> 15.7 | R8: 242T | S8: =F8 -> 0 | T8: =$N$6 -> 0 | U8: 15.5 | V8: 16.024337 | W8: 16 | X8: -0.54 | Y8: =W8+X8 -> 15.46 | AE8: 242T | AG8: =$AA$6 -> 0 | AH8: 15.5 | AI8: 16.125519 | AJ8: 16 | AK8: -0.12 | AL8: =AJ8+AK8 -> 15.88
E9: SU | F9: X | G9: =$A$6 -> 0 | H9: 14.5 | I9: 14.79 | J9: 15 | K9: -0.3 | L9: =J9+K9 -> 14.7 | R9: SU | S9: =F9 -> X | T9: =$N$6 -> 0 | U9: 14.5 | V9: 15.591865 | W9: 15 | X9: -0.54 | Y9: =W9+X9 -> 14.46 | AE9: SU | AF9: X | AG9: =$AA$6 -> 0 | AH9: 14.5 | AI9: 14.929887 | AJ9: 15 | AK9: -0.12 | AL9: =AJ9+AK9 -> 14.88
C10: 5260 | D10: 52 | E10: 26T | F10: =F5 -> 0 | G10: =$A$6 -> 0 | H10: 14.5 | I10: 14.76 | J10: 15 | K10: -0.3 | L10: =J10+K10 -> 14.7 | P10: 5600 | Q10: 120 | R10: 26T | S10: =F10 -> 0 | T10: =$N$6 -> 0 | U10: 14.5 | V10: 15.668297 | W10: 15 | X10: -0.54 | Y10: =W10+X10 -> 14.46 | AC10: 5785 | AD10: 157 | AE10: 26T | AF10: =AF5 -> 0 | AG10: =$AA$6 -> 0 | AH10: 14.5 | AI10: 14.95066 | AJ10: 15 | AK10: -0.12 | AL10: =AJ10+AK10 -> 14.88
E11: 52T | F11: =F6 -> 0 | G11: =$A$6 -> 0 | H11: 9.5 | I11: 9.35 | J11: 10 | K11: -0.3 | L11: =J11+K11 -> 9.7 | R11: 52T | S11: =F11 -> 0 | T11: =$N$6 -> 0 | U11: 9.5 | V11: 10.161565 | W11: 10 | X11: -0.54 | Y11: =W11+X11 -> 9.46 | AE11: 52T | AF11: =AF6 -> 0 | AG11: =$AA$6 -> 0 | AH11: 9.5 | AI11: 9.8670513 | AJ11: 10 | AK11: -0.12 | AL11: =AJ11+AK11 -> 9.88
E12: 106T | F12: =F7 -> 0 | G12: =$A$6 -> 0 | H12: 11.5 | I12: 11.19 | J12: 12 | K12: -0.3 | L12: =J12+K12 -> 11.7 | R12: 106T | S12: =F12 -> 0 | T12: =$N$6 -> 0 | U12: 11.5 | V12: 11.667015 | W12: 12 | X12: -0.54 | Y12: =W12+X12 -> 11.46 | AE12: 106T | AF12: =AF7 -> 0 | AG12: =$AA$6 -> 0 | AH12: 11.5 | AI12: 12.12914 | AJ12: 12 | AK12: -0.12 | AL12: =AJ12+AK12 -> 11.88
E13: 242T | F13: =F8 -> 0 | G13: =$A$6 -> 0 | H13: 14.5 | I13: 14.08 | J13: 15 | K13: -0.3 | L13: =J13+K13 -> 14.7 | R13: 242T | S13: =F13 -> 0 | T13: =$N$6 -> 0 | U13: 14.5 | V13: 14.178886 | W13: 15 | X13: -0.54 | Y13: =W13+X13 -> 14.46 | AE13: 242T | AF13: =AF8 -> 0 | AG13: =$AA$6 -> 0 | AH13: 14.5 | AI13: 14.699928 | AJ13: 15 | AK13: -0.12 | AL13: =AJ13+AK13 -> 14.88
E14: SU | F14: =F9 -> X | G14: =$A$6 -> 0 | H14: 15.5 | I14: 15.79 | J14: 16 | K14: -0.3 | L14: =J14+K14 -> 15.7 | R14: SU | S14: =F14 -> X | T14: =$N$6 -> 0 | U14: 15.5 | V14: 16.664766 | W14: 16 | X14: -0.54 | Y14: =W14+X14 -> 15.46 | AE14: SU | AF14: X | AG14: =$AA$6 -> 0 | AH14: 15.5 | AI14: 16.48973 | AJ14: 16 | AK14: -0.12 | AL14: =AJ14+AK14 -> 15.88
C15: 5320 | D15: 64 | E15: 26T | F15: =F10 -> 0 | G15: =$A$6 -> 0 | H15: 14.5 | I15: 15.03 | J15: 15 | K15: -0.3 | L15: =J15+K15 -> 14.7 | P15: 5700 | Q15: 140 | R15: 26T | S15: =F15 -> 0 | T15: =$N$6 -> 0 | U15: 14.5 | V15: 15.912802 | W15: 15 | X15: -0.54 | Y15: =W15+X15 -> 14.46 | AC15: 5825 | AD15: 165 | AE15: 26T | AF15: =AF10 -> 0 | AG15: =$AA$6 -> 0 | AH15: 14.5 | AI15: 15.40338 | AJ15: 15 | AK15: -0.12 | AL15: =AJ15+AK15 -> 14.88
E16: 52T | F16: =F11 -> 0 | G16: =$A$6 -> 0 | H16: 14.5 | I16: 15.13 | J16: 15 | K16: -0.3 | L16: =J16+K16 -> 14.7 | R16: 52T | S16: =F16 -> 0 | T16: =$N$6 -> 0 | U16: 14.5 | V16: 15.712768 | W16: 15 | X16: -0.54 | Y16: =W16+X16 -> 14.46 | AE16: 52T | AF16: =AF11 -> 0 | AG16: =$AA$6 -> 0 | AH16: 14.5 | AI16: 15.873245 | AJ16: 15 | AK16: -0.12 | AL16: =AJ16+AK16 -> 14.88
E17: 106T | F17: =F12 -> 0 | G17: =$A$6 -> 0 | H17: 9.5 | I17: 10.09 | J17: 10 | K17: -0.3 | L17: =J17+K17 -> 9.7 | R17: 106T | S17: =F17 -> 0 | T17: =$N$6 -> 0 | U17: 9.5 | V17: 10.413086 | W17: 10 | X17: -0.54 | Y17: =W17+X17 -> 9.46 | AE17: 106T | AF17: =AF12 -> 0 | AG17: =$AA$6 -> 0 | AH17: 9.5 | AI17: 10.15908 | AJ17: 10 | AK17: -0.12 | AL17: =AJ17+AK17 -> 9.88
E18: 242T | F18: =F13 -> 0 | G18: =$A$6 -> 0 | H18: 11.5 | I18: 11.58 | J18: 12 | K18: -0.3 | L18: =J18+K18 -> 11.7 | R18: 242T | S18: =F18 -> 0 | T18: =$N$6 -> 0 | U18: 11.5 | V18: 11.632209 | W18: 12 | X18: -0.54 | Y18: =W18+X18 -> 11.46 | AE18: 242T | AF18: =AF13 -> 0 | AG18: =$AA$6 -> 0 | AH18: 11.5 | AI18: 12.108877 | AJ18: 12 | AK18: -0.12 | AL18: =AJ18+AK18 -> 11.88
E19: SU | F19: =F14 -> X | G19: =$A$6 -> 0 | H19: 14.5 | I19: 14.69 | J19: 15 | K19: -0.3 | L19: =J19+K19 -> 14.7 | R19: SU | S19: =F19 -> X | T19: =$N$6 -> 0 | U19: 14.5 | V19: 14.832931 | W19: 15 | X19: -0.54 | Y19: =W19+X19 -> 14.46 | AE19: SU | AF19: X | AG19: =$AA$6 -> 0 | AH19: 14.5 | AI19: 15.332497 | AJ19: 15 | AK19: -0.12 | AL19: =AJ19+AK19 -> 14.88
A20: Worst Data Rate | B20: 802.11ax HE40 | C20: 5190 | D20: 38 | E20: 26T | G20: =$A$21 -> 0 | H20: 15.5 | I20: 16.03 | J20: 10 | K20: -0.3 | L20: =J20+K20 -> 9.7 | N20: Worst Data Rate | O20: 802.11ax HE40 | P20: 5510 | Q20: 102 | R20: 26T | S20: =F20 -> 0 | T20: =$N$21 -> 0 | U20: 15.5 | V20: 16.502149 | W20: 10 | X20: -0.54 | Y20: =W20+X20 -> 9.46 | AA20: Worst Data Rate | AB20: 802.11ax HE40 | AC20: 5755 | AD20: 151 | AE20: 26T | AG20: =$AA$21 -> 0 | AH20: 15.5 | AI20: 16.809081 | AJ20: 10 | AK20: -0.12 | AL20: =AJ20+AK20 -> 9.88
E21: 52T | G21: =$A$21 -> 0 | H21: 14.5 | I21: 15.36 | J21: 12 | K21: -0.3 | L21: =J21+K21 -> 11.7 | R21: 52T | S21: =F21 -> 0 | T21: =$N$21 -> 0 | U21: 14.5 | V21: 15.806988 | W21: 12 | X21: -0.54 | Y21: =W21+X21 -> 11.46 | AE21: 52T | AG21: =$AA$21 -> 0 | AH21: 14.5 | AI21: 16.080076 | AJ21: 12 | AK21: -0.12 | AL21: =AJ21+AK21 -> 11.88
E22: 106T | G22: =$A$21 -> 0 | H22: 14.5 | I22: 15.69 | J22: 15 | K22: -0.3 | L22: =J22+K22 -> 14.7 | R22: 106T | S22: =F22 -> 0 | T22: =$N$21 -> 0 | U22: 14.5 | V22: 16.454309 | W22: 15 | X22: -0.54 | Y22: =W22+X22 -> 14.46 | AE22: 106T | AG22: =$AA$21 -> 0 | AH22: 14.5 | AI22: 15.992503 | AJ22: 15 | AK22: -0.12 | AL22: =AJ22+AK22 -> 14.88
E23: 242T | G23: =$A$21 -> 0 | H23: 9.5 | I23: 9.58 | J23: 16 | K23: -0.3 | L23: =J23+K23 -> 15.7 | R23: 242T | S23: =F23 -> 0 | T23: =$N$21 -> 0 | U23: 9.5 | V23: 10.346452 | W23: 16 | X23: -0.54 | Y23: =W23+X23 -> 15.46 | AE23: 242T | AG23: =$AA$21 -> 0 | AH23: 9.5 | AI23: 10.542455 | AJ23: 16 | AK23: -0.12 | AL23: =AJ23+AK23 -> 15.88
E24: 484T | G24: =$A$21 -> 0 | H24: 11.5 | I24: 10.95 | J24: 15 | K24: -0.3 | L24: =J24+K24 -> 14.7 | R24: 484T | S24: =F24 -> 0 | T24: =$N$21 -> 0 | U24: 11.5 | V24: 11.241043 | W24: 15 | X24: -0.54 | Y24: =W24+X24 -> 14.46 | AE24: 484T | AG24: =$AA$21 -> 0 | AH24: 11.5 | AI24: 11.441665 | AJ24: 15 | AK24: -0.12 | AL24: =AJ24+AK24 -> 14.88
E25: SU | F25: X | G25: =$A$21 -> 0 | H25: 14.5 | I25: 15.11 | J25: 15 | K25: -0.3 | L25: =J25+K25 -> 14.7 | R25: SU | S25: =F25 -> X | T25: =$N$21 -> 0 | U25: 14.5 | V25: 16.063471 | W25: 15 | X25: -0.54 | Y25: =W25+X25 -> 14.46 | AE25: SU | AF25: X | AG25: =$AA$21 -> 0 | AH25: 14.5 | AI25: 15.33722 | AJ25: 15 | AK25: -0.12 | AL25: =AJ25+AK25 -> 14.88
C26: 5270 | D26: 54 | E26: 26T | F26: =F20 -> 0 | G26: =$A$21 -> 0 | H26: 15.5 | I26: 15.36 | J26: 10 | K26: -0.3 | L26: =J26+K26 -> 9.7 | P26: 5590 | Q26: 118 | R26: 26T | S26: =F26 -> 0 | T26: =$N$21 -> 0 | U26: 15.5 | V26: 15.43203 | W26: 10 | X26: -0.54 | Y26: =W26+X26 -> 9.46 | AC26: 5795 | AD26: 159 | AE26: 26T | AF26: =AF20 -> 0 | AG26: =$AA$21 -> 0 | AH26: 15.5 | AI26: 15.97634 | AJ26: 10 | AK26: -0.12 | AL26: =AJ26+AK26 -> 9.88
E27: 52T | F27: =F21 -> 0 | G27: =$A$21 -> 0 | H27: 14.5 | I27: 14.04 | J27: 12 | K27: -0.3 | L27: =J27+K27 -> 11.7 | R27: 52T | S27: =F27 -> 0 | T27: =$N$21 -> 0 | U27: 14.5 | V27: 14.093916 | W27: 12 | X27: -0.54 | Y27: =W27+X27 -> 11.46 | AE27: 52T | AF27: =AF21 -> 0 | AG27: =$AA$21 -> 0 | AH27: 14.5 | AI27: 15.016557 | AJ27: 12 | AK27: -0.12 | AL27: =AJ27+AK27 -> 11.88
E28: 106T | F28: =F22 -> 0 | G28: =$A$21 -> 0 | H28: 14.5 | I28: 14.38 | J28: 15 | K28: -0.3 | L28: =J28+K28 -> 14.7 | R28: 106T | S28: =F28 -> 0 | T28: =$N$21 -> 0 | U28: 14.5 | V28: 14.544796 | W28: 15 | X28: -0.54 | Y28: =W28+X28 -> 14.46 | AE28: 106T | AF28: =AF22 -> 0 | AG28: =$AA$21 -> 0 | AH28: 14.5 | AI28: 14.610507 | AJ28: 15 | AK28: -0.12 | AL28: =AJ28+AK28 -> 14.88
E29: 242T | F29: =F23 -> 0 | G29: =$A$21 -> 0 | H29: 9.5 | I29: 9.26 | J29: 16 | K29: -0.3 | L29: =J29+K29 -> 15.7 | R29: 242T | S29: =F29 -> 0 | T29: =$N$21 -> 0 | U29: 9.5 | V29: 10.10497 | W29: 16 | X29: -0.54 | Y29: =W29+X29 -> 15.46 | AE29: 242T | AF29: =AF23 -> 0 | AG29: =$AA$21 -> 0 | AH29: 9.5 | AI29: 9.7374437 | AJ29: 16 | AK29: -0.12 | AL29: =AJ29+AK29 -> 15.88
E30: 484T | F30: =F24 -> 0 | G30: =$A$21 -> 0 | H30: 11.5 | I30: 11.09 | J30: 15 | K30: -0.3 | L30: =J30+K30 -> 14.7 | R30: 484T | S30: =F30 -> 0 | T30: =$N$21 -> 0 | U30: 11.5 | V30: 11.850733 | W30: 15 | X30: -0.54 | Y30: =W30+X30 -> 14.46 | AE30: 484T | AF30: =AF24 -> 0 | AG30: =$AA$21 -> 0 | AH30: 11.5 | AI30: 11.747354 | AJ30: 15 | AK30: -0.12 | AL30: =AJ30+AK30 -> 14.88
E31: SU | F31: =F25 -> X | G31: =$A$21 -> 0 | H31: 14.5 | I31: 15.06 | J31: 15 | K31: -0.3 | L31: =J31+K31 -> 14.7 | R31: SU | S31: =F31 -> X | T31: =$N$21 -> 0 | U31: 14.5 | V31: 15.724819 | W31: 15 | X31: -0.54 | Y31: =W31+X31 -> 14.46 | AE31: SU | AF31: =AF25 -> X | AG31: =$AA$21 -> 0 | AH31: 14.5 | AI31: 16.02344 | AJ31: 15 | AK31: -0.12 | AL31: =AJ31+AK31 -> 14.88
C32: 5310 | D32: 62 | E32: 26T | F32: =F26 -> 0 | G32: =$A$21 -> 0 | H32: 15.5 | I32: 15.77 | J32: 10 | K32: -0.3 | L32: =J32+K32 -> 9.7 | P32: 5670 | Q32: 134 | R32: 26T | S32: =F32 -> 0 | T32: =$N$21 -> 0 | U32: 15.5 | V32: 16.336844 | W32: 10 | X32: -0.54 | Y32: =W32+X32 -> 9.46 | AA32: Worst Data Rate | AB32: 802.11ax HE80 | AC32: 5775 | AD32: 155 | AE32: 26T | AG32: =$AA$33 -> 0 | AH32: 15.5 | AI32: 16.588076 | AJ32: 10 | AK32: -0.12 | AL32: =AJ32+AK32 -> 9.88
E33: 52T | F33: =F27 -> 0 | G33: =$A$21 -> 0 | H33: 14.5 | I33: 13.91 | J33: 12 | K33: -0.3 | L33: =J33+K33 -> 11.7 | R33: 52T | S33: =F33 -> 0 | T33: =$N$21 -> 0 | U33: 14.5 | V33: 14.148429 | W33: 12 | X33: -0.54 | Y33: =W33+X33 -> 11.46 | AE33: 52T | AG33: =$AA$33 -> 0 | AH33: 14.5 | AI33: 14.713943 | AJ33: 12 | AK33: -0.12 | AL33: =AJ33+AK33 -> 11.88
E34: 106T | F34: =F28 -> 0 | G34: =$A$21 -> 0 | H34: 14.5 | I34: 14.16 | J34: 15 | K34: -0.3 | L34: =J34+K34 -> 14.7 | R34: 106T | S34: =F34 -> 0 | T34: =$N$21 -> 0 | U34: 14.5 | V34: 15.090401 | W34: 15 | X34: -0.54 | Y34: =W34+X34 -> 14.46 | AE34: 106T | AG34: =$AA$33 -> 0 | AH34: 14.5 | AI34: 14.52711 | AJ34: 15 | AK34: -0.12 | AL34: =AJ34+AK34 -> 14.88
E35: 242T | F35: =F29 -> 0 | G35: =$A$21 -> 0 | H35: 9.5 | I35: 9.12 | J35: 16 | K35: -0.3 | L35: =J35+K35 -> 15.7 | R35: 242T | S35: =F35 -> 0 | T35: =$N$21 -> 0 | U35: 9.5 | V35: 9.9115649 | W35: 16 | X35: -0.54 | Y35: =W35+X35 -> 15.46 | AE35: 242T | AG35: =$AA$33 -> 0 | AH35: 9.5 | AI35: 9.7192705 | AJ35: 16 | AK35: -0.12 | AL35: =AJ35+AK35 -> 15.88
E36: 484T | F36: =F30 -> 0 | G36: =$A$21 -> 0 | H36: 11.5 | I36: 10.85 | J36: 15 | K36: -0.3 | L36: =J36+K36 -> 14.7 | R36: 484T | S36: =F36 -> 0 | T36: =$N$21 -> 0 | U36: 11.5 | V36: 11.736106 | W36: 15 | X36: -0.54 | Y36: =W36+X36 -> 14.46 | AE36: 484T | AG36: =$AA$33 -> 0 | AH36: 11.5 | AI36: 11.784361 | AJ36: 15 | AK36: -0.12 | AL36: =AJ36+AK36 -> 14.88
E37: SU | F37: =F31 -> X | G37: =$A$21 -> 0 | H37: 14.5 | I37: 15.31 | J37: 15 | K37: -0.3 | L37: =J37+K37 -> 14.7 | R37: SU | S37: =F37 -> X | T37: =$N$21 -> 0 | U37: 14.5 | V37: 15.434997 | W37: 15 | X37: -0.54 | Y37: =W37+X37 -> 14.46 | AE37: 996T | AG37: =$AA$33 -> 0 | AH37: 14.5 | AI37: 16.049385 | AJ37: 15 | AK37: -0.12 | AL37: =AJ37+AK37 -> 14.88
A38: Worst Data Rate | B38: 802.11ax HE80 | C38: 5210 | D38: 42 | E38: 26T | G38: =$A$39 -> 0 | H38: 15.5 | I38: 15.57 | J38: 10 | K38: -0.3 | L38: =J38+K38 -> 9.7 | N38: Worst Data Rate | O38: 802.11ax HE80 | P38: 5530 | Q38: 106 | R38: 26T | S38: =F38 -> 0 | T38: =$N$39 -> 0 | U38: 15.5 | V38: 15.854654 | W38: 10 | X38: -0.54 | Y38: =W38+X38 -> 9.46 | AE38: SU | AF38: X | AG38: =$AA$33 -> 0 | AH38: 15.5 | AI38: 15.601963 | AJ38: 10 | AK38: -0.12 | AL38: =AJ38+AK38 -> 9.88
E39: 52T | G39: =$A$39 -> 0 | H39: 14.5 | I39: 14.25 | J39: 12 | K39: -0.3 | L39: =J39+K39 -> 11.7 | R39: 52T | S39: =F39 -> 0 | T39: =$N$39 -> 0 | U39: 14.5 | V39: 14.366687 | W39: 12 | X39: -0.54 | Y39: =W39+X39 -> 11.46
E40: 106T | G40: =$A$39 -> 0 | H40: 14.5 | I40: 14.21 | J40: 15 | K40: -0.3 | L40: =J40+K40 -> 14.7 | R40: 106T | S40: =F40 -> 0 | T40: =$N$39 -> 0 | U40: 14.5 | V40: 15.142134 | W40: 15 | X40: -0.54 | Y40: =W40+X40 -> 14.46
E41: 242T | G41: =$A$39 -> 0 | H41: 9.5 | I41: 9.07 | J41: 16 | K41: -0.3 | L41: =J41+K41 -> 15.7 | R41: 242T | S41: =F41 -> 0 | T41: =$N$39 -> 0 | U41: 9.5 | V41: 9.7396289 | W41: 16 | X41: -0.54 | Y41: =W41+X41 -> 15.46
...

Sheet WLAN 5 GHz 802.11ax Ant2
B2: SISO (Antenna 2)
B3: 5.2 GHz 802.11ax | O3: 5.5 GHz 802.11ax | AB3: 5.8 GHz 802.11ax
B4: Mode | C4: Freq. (㎒) | D4: Channel | E4: Tone | F4: Worst RU | G4: Data Rate | H4: PLS | I4: Average Power(㏈m) | J4: Tune-Up Power(㏈m) | K4: Peak Gain (dBi) | L4: E.I.R.P | O4: Mode | P4: Freq. (㎒) | Q4: Channel | R4: Tone | S4: Worst RU | T4: Data Rate | U4: PLS | V4: Average Power(㏈m) | W4: Tune-Up Power(㏈m) | X4: Peak Gain (dBi) | Y4: E.I.R.P | AB4: Mode | AC4: Freq. (㎒) | AD4: Channel | AE4: Tone | AF4: Worst RU | AG4: Data Rate | AH4: PLS | AI4: Average Power(㏈m) | AJ4: Tune-Up Power(㏈m) | AK4: Peak Gain (dBi) | AL4: E.I.R.P
A5: Worst Data Rate | B5: 802.11ax HE20 | C5: 5180 | D5: 36 | E5: 26T | F5: ='WLAN 5 GHz 802.11ax Ant1'!F5 -> 0 | G5: =$A$6 -> 0 | H5: 9.5 | I5: 9.4349578 | J5: 10 | K5: -0.14 | L5: =J5+K5 -> 9.86 | N5: Worst Data Rate | O5: 802.11ax HE20 | P5: 5500 | Q5: 100 | R5: 26T | S5: ='WLAN 5 GHz 802.11ax Ant1'!S5 -> 0 | T5: =$N$6 -> 0 | U5: 9.5 | V5: 9.9181717 | W5: 10 | X5: -0.54 | Y5: =W5+X5 -> 9.46 | AA5: Worst Data Rate | AB5: 802.11ax HE20 | AC5: 5745 | AD5: 149 | AE5: 26T | AF5: ='WLAN 5 GHz 802.11ax Ant1'!AF5 -> 0 | AG5: =$AA$6 -> 0 | AH5: 9.5 | AI5: 9.9545106 | AJ5: 10 | AK5: -0.36 | AL5: =AJ5+AK5 -> 9.64
A6: ='WLAN 5 GHz 802.11ax Ant1'!A6 -> 0 | E6: 52T | F6: ='WLAN 5 GHz 802.11ax Ant1'!F6 -> 0 | G6: =$A$6 -> 0 | H6: 11.5 | I6: 11.629974 | J6: 12 | K6: -0.14 | L6: =J6+K6 -> 11.86 | N6: ='WLAN 5 GHz 802.11ax Ant1'!N6 -> 0 | R6: 52T | S6: ='WLAN 5 GHz 802.11ax Ant1'!S6 -> 0 | T6: =$N$6 -> 0 | U6: 11.5 | V6: 11.948286 | W6: 12 | X6: -0.54 | Y6: =W6+X6 -> 11.46 | AA6: ='WLAN 5 GHz 802.11ax Ant1'!AA6 -> 0 | AE6: 52T | AF6: ='WLAN 5 GHz 802.11ax Ant1'!AF6 -> 0 | AG6: =$AA$6 -> 0 | AH6: 11.5 | AI6: 11.480382 | AJ6: 12 | AK6: -0.36 | AL6: =AJ6+AK6 -> 11.64
E7: 106T | F7: ='WLAN 5 GHz 802.11ax Ant1'!F7 -> 0 | G7: =$A$6 -> 0 | H7: 14.5 | I7: 14.404861 | J7: 15 | K7: -0.14 | L7: =J7+K7 -> 14.86 | R7: 106T | S7: ='WLAN 5 GHz 802.11ax Ant1'!S7 -> 0 | T7: =$N$6 -> 0 | U7: 14.5 | V7: 15.075364 | W7: 15 | X7: -0.54 | Y7: =W7+X7 -> 14.46 | AE7: 106T | AF7: ='WLAN 5 GHz 802.11ax Ant1'!AF7 -> 0 | AG7: =$AA$6 -> 0 | AH7: 14.5 | AI7: 14.484112 | AJ7: 15 | AK7: -0.36 | AL7: =AJ7+AK7 -> 14.64
E8: 242T | F8: ='WLAN 5 GHz 802.11ax Ant1'!F8 -> 0 | G8: =$A$6 -> 0 | H8: 15.5 | I8: 16.118967 | J8: 16 | K8: -0.14 | L8: =J8+K8 -> 15.86 | R8: 242T | S8: ='WLAN 5 GHz 802.11ax Ant1'!S8 -> 0 | T8: =$N$6 -> 0 | U8: 15.5 | V8: 16.470343 | W8: 16 | X8: -0.54 | Y8: =W8+X8 -> 15.46 | AE8: 242T | AF8: ='WLAN 5 GHz 802.11ax Ant1'!AF8 -> 0 | AG8: =$AA$6 -> 0 | AH8: 15.5 | AI8: 16.42938 | AJ8: 16 | AK8: -0.36 | AL8: =AJ8+AK8 -> 15.64
E9: SU | F9: ='WLAN 5 GHz 802.11ax Ant1'!F9 -> X | G9: =$A$6 -> 0 | H9: 14.5 | I9: 15.042048 | J9: 15 | K9: -0.14 | L9: =J9+K9 -> 14.86 | R9: SU | S9: ='WLAN 5 GHz 802.11ax Ant1'!S9 -> X | T9: =$N$6 -> 0 | U9: 14.5 | V9: 15.400378 | W9: 15 | X9: -0.54 | Y9: =W9+X9 -> 14.46 | AE9: SU | AF9: ='WLAN 5 GHz 802.11ax Ant1'!AF9 -> X | AG9: =$AA$6 -> 0 | AH9: 14.5 | AI9: 15.353226 | AJ9: 15 | AK9: -0.36 | AL9: =AJ9+AK9 -> 14.64
C10: 5260 | D10: 52 | E10: 26T | F10: ='WLAN 5 GHz 802.11ax Ant1'!F10 -> 0 | G10: =$A$6 -> 0 | H10: 14.5 | I10: 15.397853 | J10: 15 | K10: -0.14 | L10: =J10+K10 -> 14.86 | P10: 5600 | Q10: 120 | R10: 26T | S10: ='WLAN 5 GHz 802.11ax Ant1'!S10 -> 0 | T10: =$N$6 -> 0 | U10: 14.5 | V10: 15.22574 | W10: 15 | X10: -0.54 | Y10: =W10+X10 -> 14.46 | AC10: 5785 | AD10: 157 | AE10: 26T | AF10: ='WLAN 5 GHz 802.11ax Ant1'!AF10 -> 0 | AG10: =$AA$6 -> 0 | AH10: 14.5 | AI10: 15.557763 | AJ10: 15 | AK10: -0.36 | AL10: =AJ10+AK10 -> 14.64
E11: 52T | F11: ='WLAN 5 GHz 802.11ax Ant1'!F11 -> 0 | G11: =$A$6 -> 0 | H11: 9.5 | I11: 9.6890486 | J11: 10 | K11: -0.14 | L11: =J11+K11 -> 9.86 | R11: 52T | S11: ='WLAN 5 GHz 802.11ax Ant1'!S11 -> 0 | T11: =$N$6 -> 0 | U11: 9.5 | V11: 9.8741654 | W11: 10 | X11: -0.54 | Y11: =W11+X11 -> 9.46 | AE11: 52T | AF11: ='WLAN 5 GHz 802.11ax Ant1'!AF11 -> 0 | AG11: =$AA$6 -> 0 | AH11: 9.5 | AI11: 9.589279 | AJ11: 10 | AK11: -0.36 | AL11: =AJ11+AK11 -> 9.64
E12: 106T | F12: ='WLAN 5 GHz 802.11ax Ant1'!F12 -> 0 | G12: =$A$6 -> 0 | H12: 11.5 | I12: 11.856258 | J12: 12 | K12: -0.14 | L12: =J12+K12 -> 11.86 | R12: 106T | S12: ='WLAN 5 GHz 802.11ax Ant1'!S12 -> 0 | T12: =$N$6 -> 0 | U12: 11.5 | V12: 11.851165 | W12: 12 | X12: -0.54 | Y12: =W12+X12 -> 11.46 | AE12: 106T | AF12: ='WLAN 5 GHz 802.11ax Ant1'!AF12 -> 0 | AG12: =$AA$6 -> 0 | AH12: 11.5 | AI12: 12.002296 | AJ12: 12 | AK12: -0.36 | AL12: =AJ12+AK12 -> 11.64
E13: 242T | F13: ='WLAN 5 GHz 802.11ax Ant1'!F13 -> 0 | G13: =$A$6 -> 0 | H13: 14.5 | I13: 14.533693 | J13: 15 | K13: -0.14 | L13: =J13+K13 -> 14.86 | R13: 242T | S13: ='WLAN 5 GHz 802.11ax Ant1'!S13 -> 0 | T13: =$N$6 -> 0 | U13: 14.5 | V13: 14.170007 | W13: 15 | X13: -0.54 | Y13: =W13+X13 -> 14.46 | AE13: 242T | AF13: ='WLAN 5 GHz 802.11ax Ant1'!AF13 -> 0 | AG13: =$AA$6 -> 0 | AH13: 14.5 | AI13: 14.666601 | AJ13: 15 | AK13: -0.36 | AL13: =AJ13+AK13 -> 14.64
E14: SU | F14: ='WLAN 5 GHz 802.11ax Ant1'!F14 -> X | G14: =$A$6 -> 0 | H14: 15.5 | I14: 16.100195 | J14: 16 | K14: -0.14 | L14: =J14+K14 -> 15.86 | R14: SU | S14: ='WLAN 5 GHz 802.11ax Ant1'!S14 -> X | T14: =$N$6 -> 0 | U14: 15.5 | V14: 15.919521 | W14: 16 | X14: -0.54 | Y14: =W14+X14 -> 15.46 | AE14: SU | AF14: ='WLAN 5 GHz 802.11ax Ant1'!AF14 -> X | AG14: =$AA$6 -> 0 | AH14: 15.5 | AI14: 16.362483 | AJ14: 16 | AK14: -0.36 | AL14: =AJ14+AK14 -> 15.64
C15: 5320 | D15: 64 | E15: 26T | F15: ='WLAN 5 GHz 802.11ax Ant1'!F15 -> 0 | G15: =$A$6 -> 0 | H15: 14.5 | I15: 15.338748 | J15: 15 | K15: -0.14 | L15: =J15+K15 -> 14.86 | P15: 5700 | Q15: 140 | R15: 26T | S15: ='WLAN 5 GHz 802.11ax Ant1'!S15 -> 0 | T15: =$N$6 -> 0 | U15: 14.5 | V15: 15.061958 | W15: 15 | X15: -0.54 | Y15: =W15+X15 -> 14.46 | AC15: 5825 | AD15: 165 | AE15: 26T | AF15: ='WLAN 5 GHz 802.11ax Ant1'!AF15 -> 0 | AG15: =$AA$6 -> 0 | AH15: 14.5 | AI15: 15.037964 | AJ15: 15 | AK15: -0.36 | AL15: =AJ15+AK15 -> 14.64
E16: 52T | F16: ='WLAN 5 GHz 802.11ax Ant1'!F16 -> 0 | G16: =$A$6 -> 0 | H16: 14.5 | I16: 15.374951 | J16: 15 | K16: -0.14 | L16: =J16+K16 -> 14.86 | R16: 52T | S16: ='WLAN 5 GHz 802.11ax Ant1'!S16 -> 0 | T16: =$N$6 -> 0 | U16: 14.5 | V16: 15.49877 | W16: 15 | X16: -0.54 | Y16: =W16+X16 -> 14.46 | AE16: 52T | AF16: ='WLAN 5 GHz 802.11ax Ant1'!AF16 -> 0 | AG16: =$AA$6 -> 0 | AH16: 14.5 | AI16: 15.405928 | AJ16: 15 | AK16: -0.36 | AL16: =AJ16+AK16 -> 14.64
E17: 106T | F17: ='WLAN 5 GHz 802.11ax Ant1'!F17 -> 0 | G17: =$A$6 -> 0 | H17: 9.5 | I17: 10.93736 | J17: 10 | K17: -0.14 | L17: =J17+K17 -> 9.86 | R17: 106T | S17: ='WLAN 5 GHz 802.11ax Ant1'!S17 -> 0 | T17: =$N$6 -> 0 | U17: 9.5 | V17: 10.197809 | W17: 10 | X17: -0.54 | Y17: =W17+X17 -> 9.46 | AE17: 106T | AF17: ='WLAN 5 GHz 802.11ax Ant1'!AF17 -> 0 | AG17: =$AA$6 -> 0 | AH17: 9.5 | AI17: 10.830829 | AJ17: 10 | AK17: -0.36 | AL17: =AJ17+AK17 -> 9.64
E18: 242T | F18: ='WLAN 5 GHz 802.11ax Ant1'!F18 -> 0 | G18: =$A$6 -> 0 | H18: 11.5 | I18: 12.45604 | J18: 12 | K18: -0.14 | L18: =J18+K18 -> 11.86 | R18: 242T | S18: ='WLAN 5 GHz 802.11ax Ant1'!S18 -> 0 | T18: =$N$6 -> 0 | U18: 11.5 | V18: 12.400302 | W18: 12 | X18: -0.54 | Y18: =W18+X18 -> 11.46 | AE18: 242T | AF18: ='WLAN 5 GHz 802.11ax Ant1'!AF18 -> 0 | AG18: =$AA$6 -> 0 | AH18: 11.5 | AI18: 12.392146 | AJ18: 12 | AK18: -0.36 | AL18: =AJ18+AK18 -> 11.64
E19: SU | F19: ='WLAN 5 GHz 802.11ax Ant1'!F19 -> X | G19: =$A$6 -> 0 | H19: 14.5 | I19: 15.125104 | J19: 15 | K19: -0.14 | L19: =J19+K19 -> 14.86 | R19: SU | S19: ='WLAN 5 GHz 802.11ax Ant1'!S19 -> X | T19: =$N$6 -> 0 | U19: 14.5 | V19: 15.606528 | W19: 15 | X19: -0.54 | Y19: =W19+X19 -> 14.46 | AE19: SU | AF19: ='WLAN 5 GHz 802.11ax Ant1'!AF19 -> X | AG19: =$AA$6 -> 0 | AH19: 14.5 | AI19: 15.3639 | AJ19: 15 | AK19: -0.36 | AL19: =AJ19+AK19 -> 14.64
A20: Worst Data Rate | B20: 802.11ax HE40 | C20: 5190 | D20: 38 | E20: 26T | F20: ='WLAN 5 GHz 802.11ax Ant1'!F20 -> 0 | G20: =$A$21 -> 0 | H20: 15.5 | I20: 16.747251 | J20: 10 | K20: -0.14 | L20: =J20+K20 -> 9.86 | N20: Worst Data Rate | O20: 802.11ax HE40 | P20: 5510 | Q20: 102 | R20: 26T | S20: ='WLAN 5 GHz 802.11ax Ant1'!S20 -> 0 | T20: =$N$21 -> 0 | U20: 15.5 | V20: 16.867947 | W20: 10 | X20: -0.54 | Y20: =W20+X20 -> 9.46 | AA20: Worst Data Rate | AB20: 802.11ax HE40 | AC20: 5755 | AD20: 151 | AE20: 26T | AF20: ='WLAN 5 GHz 802.11ax Ant1'!AF20 -> 0 | AG20: =$AA$21 -> 0 | AH20: 15.5 | AI20: 16.680328 | AJ20: 10 | AK20: -0.36 | AL20: =AJ20+AK20 -> 9.64
A21: ='WLAN 5 GHz 802.11ax Ant1'!A21 -> 0 | E21: 52T | F21: ='WLAN 5 GHz 802.11ax Ant1'!F21 -> 0 | G21: =$A$21 -> 0 | H21: 14.5 | I21: 15.595467 | J21: 12 | K21: -0.14 | L21: =J21+K21 -> 11.86 | N21: ='WLAN 5 GHz 802.11ax Ant1'!N21 -> 0 | R21: 52T | S21: ='WLAN 5 GHz 802.11ax Ant1'!S21 -> 0 | T21: =$N$21 -> 0 | U21: 14.5 | V21: 16.302375 | W21: 12 | X21: -0.54 | Y21: =W21+X21 -> 11.46 | AA21: ='WLAN 5 GHz 802.11ax Ant1'!AA21 -> 0 | AE21: 52T | AF21: ='WLAN 5 GHz 802.11ax Ant1'!AF21 -> 0 | AG21: =$AA$21 -> 0 | AH21: 14.5 | AI21: 15.774996 | AJ21: 12 | AK21: -0.36 | AL21: =AJ21+AK21 -> 11.64
E22: 106T | F22: ='WLAN 5 GHz 802.11ax Ant1'!F22 -> 0 | G22: =$A$21 -> 0 | H22: 14.5 | I22: 16.592828 | J22: 15 | K22: -0.14 | L22: =J22+K22 -> 14.86 | R22: 106T | S22: ='WLAN 5 GHz 802.11ax Ant1'!S22 -> 0 | T22: =$N$21 -> 0 | U22: 14.5 | V22: 16.294964 | W22: 15 | X22: -0.54 | Y22: =W22+X22 -> 14.46 | AE22: 106T | AF22: ='WLAN 5 GHz 802.11ax Ant1'!AF22 -> 0 | AG22: =$AA$21 -> 0 | AH22: 14.5 | AI22: 16.469123 | AJ22: 15 | AK22: -0.36 | AL22: =AJ22+AK22 -> 14.64
E23: 242T | F23: ='WLAN 5 GHz 802.11ax Ant1'!F23 -> 0 | G23: =$A$21 -> 0 | H23: 9.5 | I23: 9.7322811 | J23: 16 | K23: -0.14 | L23: =J23+K23 -> 15.86 | R23: 242T | S23: ='WLAN 5 GHz 802.11ax Ant1'!S23 -> 0 | T23: =$N$21 -> 0 | U23: 9.5 | V23: 9.8255897 | W23: 16 | X23: -0.54 | Y23: =W23+X23 -> 15.46 | AE23: 242T | AF23: ='WLAN 5 GHz 802.11ax Ant1'!AF23 -> 0 | AG23: =$AA$21 -> 0 | AH23: 9.5 | AI23: 10.100196 | AJ23: 16 | AK23: -0.36 | AL23: =AJ23+AK23 -> 15.64
